<?xml version="1.0" ?>
<!-- =================================================================================== -->
<!-- |    This document was autogenerated by xacro from moria.urdf.xacro               | -->
<!-- |    EDITING THIS FILE BY HAND IS NOT RECOMMENDED                                 | -->
<!-- =================================================================================== -->
<robot name="moria">
  <!-- NEED A FOOTPRINT-->
  <link name="base_footprint"/>
  <!-- ........:::::::: ROBOT DEFINITIONS ::::::::........-->
  <!-- BASE OF THE ROBOT-->
  <joint name="base_footprint_joint" type="fixed">
    <parent link="base_footprint"/>
    <child link="base_link"/>
    <origin xyz="0 0 0"/>
  </joint>
  <link name="base_link">
    <visual>
      <origin rpy="0 0 0" xyz="0 0 0"/>
      <geometry>
        <mesh filename="package://moria_description/meshes/base_link.STL"/>
        &gt;
            
      </geometry>
      <material name="">
        <color rgba="0.0667 0.2431 0.4078 1"/>
        &quot;
            
      </material>
    </visual>
    <collision>
      <origin rpy="0 0 0" xyz="0 0 0"/>
      <geometry>
        <mesh filename="package://moria_description/meshes/base_link.STL"/>
      </geometry>
    </collision>
    <inertial>
      <origin rpy="0 0 0" xyz="0 0 0"/>
      <mass value="4.44"/>
      <inertia ixx="0.02" ixy="0.0" ixz="0.0" iyy="0.04" iyz="0.0" izz="0.05"/>
    </inertial>
  </link>
  <!-- FRONT WHEEL-->
  <joint name="front_base_joint" type="fixed">
    <origin rpy="0 0 0" xyz="0.23 0 0"/>
    <parent link="base_link"/>
    <child link="front_base"/>
  </joint>
  <link name="front_base">
    <visual>
      <origin rpy="0 0 0" xyz="0 0 0"/>
      <geometry>
        <mesh filename="package://moria_description/meshes/front_base.STL"/>
        &gt;
            
      </geometry>
      <material name="">
        <color rgba="0.0667 0.2431 0.4078 1"/>
        &quot;
            
      </material>
    </visual>
    <collision>
      <origin rpy="0 0 0" xyz="0 0 0"/>
      <geometry>
        <mesh filename="package://moria_description/meshes/front_base.STL"/>
      </geometry>
    </collision>
    <inertial>
      <origin rpy="0 0 0" xyz="0 0 0"/>
      <mass value="0.003"/>
      <inertia ixx="5.21" ixy="0.0" ixz="0.0" iyy="7.95" iyz="0.0" izz="1.32"/>
    </inertial>
  </link>
  <joint name="front_radial_joint" type="continuous">
    <parent link="front_base"/>
    <child link="front_radial"/>
    <origin rpy="0 0 1.57" xyz="0 0 0"/>
    <axis xyz="0 0 1"/>
  </joint>
  <link name="front_radial">
    <visual>
      <origin rpy="0 0 0" xyz="0 0 0"/>
      <geometry>
        <mesh filename="package://moria_description/meshes/front_rad.STL"/>
        &gt;
            
      </geometry>
      <material name="">
        <color rgba="0.0667 0.2431 0.4078 1"/>
        &quot;
            
      </material>
    </visual>
    <collision>
      <origin rpy="0 0 0" xyz="0 0 0"/>
      <geometry>
        <mesh filename="package://moria_description/meshes/front_rad.STL"/>
      </geometry>
    </collision>
    <inertial>
      <origin rpy="0 0 0" xyz="0 0 0"/>
      <mass value="0.01"/>
      <inertia ixx="0.0" ixy="0.0" ixz="0.0" iyy="0.0" iyz="0.0" izz="0.0"/>
    </inertial>
  </link>
</robot>
