<?xml version="1.0" ?>
<!-- =================================================================================== -->
<!-- |    This document was autogenerated by xacro from moria.urdf.xacro               | -->
<!-- |    EDITING THIS FILE BY HAND IS NOT RECOMMENDED                                 | -->
<!-- =================================================================================== -->
<robot name="moria">
  <!-- Footprint -->
  <link name="base_footprint"/>
  <!-- Base of the Robot -->
  <joint name="base_footprint_joint" type="fixed">
    <parent link="base_footprint"/>
    <child link="base_link"/>
    <origin xyz="0 0 0"/>
  </joint>
  <link name="base_link">
    <visual>
      <origin rpy="0 0 0" xyz="0 0 0"/>
      <geometry>
        <mesh filename="package://moria_description/meshes/base_link.STL"/>
      </geometry>
      <material name="blue">
        <color rgba="0.0667 0.2431 0.4078 1"/>
      </material>
    </visual>
    <collision>
      <origin rpy="0 0 0" xyz="0 0 0"/>
      <geometry>
        <mesh filename="package://moria_description/meshes/base_link.STL"/>
      </geometry>
    </collision>
    <inertial>
      <origin rpy="0 0 0" xyz="0 0 0"/>
      <mass value="4.44"/>
      <inertia ixx="0.02125" ixy="0.0" ixz="0.00001" iyy="0.04177" iyz="0.0" izz="0.04948"/>
    </inertial>
  </link>
  <!-- FRONT WHEEL -->
  <joint name="front_base_joint" type="fixed">
    <origin rpy="0 0 0" xyz="0.23 0 0"/>
    <parent link="base_link"/>
    <child link="front_base"/>
  </joint>
  <link name="front_base">
    <visual>
      <origin rpy="0 0 0" xyz="0 0 0"/>
      <geometry>
        <mesh filename="package://moria_description/meshes/front_base.STL"/>
      </geometry>
      <material name="blue">
        <color rgba="0.0667 0.2431 0.4078 1"/>
      </material>
    </visual>
    <collision>
      <origin rpy="0 0 0" xyz="0 0 0"/>
      <geometry>
        <mesh filename="package://moria_description/meshes/front_base.STL"/>
      </geometry>
    </collision>
    <inertial>
      <origin rpy="0 0 0" xyz="0 0 0"/>
      <mass value="0.003"/>
      <inertia ixx="0.0001" ixy="0.0" ixz="0.0" iyy="0.0002" iyz="0.0" izz="0.0001"/>
    </inertial>
  </link>
  <joint name="front_radial_joint" type="continuous">
    <parent link="front_base"/>
    <child link="front_radial"/>
    <origin rpy="0 0 -1.5708" xyz="0 0 0"/>
    <axis xyz="0 0 1"/>
  </joint>
  <link name="front_radial">
    <visual>
      <origin rpy="0 0 0" xyz="0 0 0"/>
      <geometry>
        <mesh filename="package://moria_description/meshes/front_rad.STL"/>
      </geometry>
      <material name="blue">
        <color rgba="0.0667 0.2431 0.4078 1"/>
      </material>
    </visual>
    <collision>
      <origin rpy="0 0 0" xyz="0 0 0"/>
      <geometry>
        <mesh filename="package://moria_description/meshes/front_rad.STL"/>
      </geometry>
    </collision>
    <inertial>
      <origin rpy="0 0 0" xyz="0 0 0"/>
      <mass value="0.01"/>
      <inertia ixx="2.54E-06" ixy="0.0" ixz="0.0" iyy="2.17E-06" iyz="0.0" izz="3.02E-06"/>
    </inertial>
  </link>
  <joint name="front_wheel_joint" type="continuous">
    <parent link="front_radial"/>
    <child link="front_wheel"/>
    <origin rpy="1.5708 0 1.5708" xyz="0 -0.022 -0.035"/>
    <axis xyz="0 0 -1"/>
  </joint>
  <link name="front_wheel">
    <visual>
      <origin rpy="0 0 0" xyz="0 0 0"/>
      <geometry>
        <mesh filename="package://moria_description/meshes/front_wheel.STL"/>
      </geometry>
      <material name="cyan">
        <color rgba="0.3137 0.6941 0.7843 1"/>
      </material>
    </visual>
    <collision>
      <origin rpy="0 0 0" xyz="0 0 0"/>
      <geometry>
        <mesh filename="package://moria_description/meshes/front_wheel.STL"/>
      </geometry>
    </collision>
    <inertial>
      <origin rpy="0 0 0" xyz="0 0 0"/>
      <mass value="0.006"/>
      <inertia ixx="4.60E-07" ixy="0.0" ixz="0.0" iyy="4.60E-07" iyz="0.0" izz="8.66E-07"/>
    </inertial>
  </link>
  <!-- RIGHT WHEEL-->
  <joint name="right_motor_joint" type="fixed">
    <parent link="base_link"/>
    <child link="right_motor"/>
    <origin rpy="0 0 0" xyz="0 -0.096 -0.02"/>
  </joint>
  <link name="right_motor">
    <visual>
      <origin rpy="0 0 0" xyz="0 0 0"/>
      <geometry>
        <mesh filename="package://moria_description/meshes/right_motor.STL"/>
      </geometry>
      <material name="blue">
        <color rgba="0.0667 0.2431 0.4078 1"/>
      </material>
    </visual>
    <collision>
      <origin rpy="0 0 0" xyz="0 0 0"/>
      <geometry>
        <mesh filename="package://moria_description/meshes/right_motor.STL"/>
      </geometry>
    </collision>
    <inertial>
      <origin rpy="0 0 0" xyz="0 0 0"/>
      <mass value="0.11"/>
      <inertia ixx="0.00003" ixy="0.0" ixz="0.0" iyy="0.00005" iyz="0.0" izz="0.00006"/>
    </inertial>
  </link>
  <joint name="right_wheel_joint" type="continuous">
    <parent link="right_motor"/>
    <child link="right_wheel"/>
    <origin rpy="-1.5708 0 0" xyz="0 -0.076 0"/>
    <axis xyz="0 0 1"/>
  </joint>
  <link name="right_wheel">
    <visual>
      <origin rpy="0 0 0" xyz="0 0 0"/>
      <geometry>
        <mesh filename="package://moria_description/meshes/right_wheel.STL"/>
      </geometry>
      <material name="cyan">
        <color rgba="0.3137 0.6941 0.7843 1"/>
      </material>
    </visual>
    <collision>
      <origin rpy="0 0 0" xyz="0 0 0"/>
      <geometry>
        <mesh filename="package://moria_description/meshes/right_wheel.STL"/>
      </geometry>
    </collision>
    <inertial>
      <origin rpy="0 0 0" xyz="0 0 0"/>
      <mass value="0.09111"/>
      <inertia ixx="0.00003" ixy="0.0" ixz="0.0" iyy="0.00003" iyz="0.0" izz="0.00004"/>
    </inertial>
  </link>
  <!-- LEFT WHEEL-->
  <joint name="left_motor_joint" type="fixed">
    <parent link="base_link"/>
    <child link="left_motor"/>
    <origin rpy="0 0 0" xyz="0 0.096 -0.02"/>
  </joint>
  <link name="left_motor">
    <visual>
      <origin rpy="0 0 0" xyz="0 0 0"/>
      <geometry>
        <mesh filename="package://moria_description/meshes/left_motor.STL"/>
      </geometry>
      <material name="blue">
        <color rgba="0.0667 0.2431 0.4078 1"/>
      </material>
    </visual>
    <collision>
      <origin rpy="0 0 0" xyz="0 0 0"/>
      <geometry>
        <mesh filename="package://moria_description/meshes/left_motor.STL"/>
      </geometry>
    </collision>
    <inertial>
      <origin rpy="0 0 0" xyz="0 0 0"/>
      <mass value="0.11"/>
      <inertia ixx="0.00003" ixy="0.0" ixz="0.0" iyy="0.00005" iyz="0.0" izz="0.00006"/>
    </inertial>
  </link>
  <joint name="left_wheel_joint" type="continuous">
    <parent link="left_motor"/>
    <child link="left_wheel"/>
    <origin rpy="1.5708 0 0" xyz="0 0.076 0"/>
    <axis xyz="0 0 -1"/>
  </joint>
  <link name="left_wheel">
    <visual>
      <origin rpy="0 0 0" xyz="0 0 0"/>
      <geometry>
        <mesh filename="package://moria_description/meshes/left_wheel.STL"/>
      </geometry>
      <material name="cyan">
        <color rgba="0.3137 0.6941 0.7843 1"/>
      </material>
    </visual>
    <collision>
      <origin rpy="0 0 0" xyz="0 0 0"/>
      <geometry>
        <mesh filename="package://moria_description/meshes/left_wheel.STL"/>
      </geometry>
    </collision>
    <inertial>
      <origin rpy="0 0 0" xyz="0 0 0"/>
      <mass value="0.09111"/>
      <inertia ixx="0.00003" ixy="0.0" ixz="0.0" iyy="0.00003" iyz="0.0" izz="0.00004"/>
    </inertial>
  </link>
  <!-- LEG -->
  <joint name="leg_joint" type="fixed">
    <parent link="base_link"/>
    <child link="leg"/>
    <origin rpy="0 0 0" xyz="0.076 0 0.185"/>
  </joint>
  <link name="leg">
    <visual>
      <origin rpy="0 0 0" xyz="0 0 0"/>
      <geometry>
        <mesh filename="package://moria_description/meshes/leg.STL"/>
      </geometry>
      <material name="blue">
        <color rgba="0.0667 0.2431 0.4078 1"/>
      </material>
    </visual>
    <collision>
      <origin rpy="0 0 0" xyz="0 0 0"/>
      <geometry>
        <mesh filename="package://moria_description/meshes/leg.STL"/>
      </geometry>
    </collision>
    <inertial>
      <origin rpy="0 0 0" xyz="0 0 0"/>
      <mass value="2.366"/>
      <inertia ixx="0.07510" ixy="0.00008" ixz="-0.00377" iyy="0.07190" iyz="0.00005" izz="0.02825"/>
    </inertial>
  </link>
  <!-- BODY-->
  <joint name="body_link" type="fixed">
    <parent link="leg"/>
    <child link="body"/>
    <origin rpy="0 0 0" xyz="0 0 0.465"/>
  </joint>
  <link name="body">
    <visual>
      <origin rpy="0 0 0" xyz="0 0 0"/>
      <geometry>
        <mesh filename="package://moria_description/meshes/body.STL"/>
      </geometry>
      <material name="blue">
        <color rgba="0.0667 0.2431 0.4078 1"/>
      </material>
    </visual>
    <collision>
      <origin rpy="0 0 0" xyz="0 0 0"/>
      <geometry>
        <mesh filename="package://moria_description/meshes/body.STL"/>
      </geometry>
    </collision>
    <inertial>
      <origin rpy="0 0 0" xyz="0 0 0"/>
      <mass value="2.80832"/>
      <inertia ixx="0.05159" ixy="0.0" ixz="-0.00006" iyy="0.03871" iyz="-0.00004" izz="0.02383"/>
    </inertial>
  </link>
  <!-- HEAD-->
  <joint name="neck_joint" type="revolute">
    <parent link="body"/>
    <child link="neck"/>
    <origin rpy="0 0 1.5708" xyz="0.0092 0.0004 0.5471"/>
    <axis xyz="0 0 1"/>
    <limit effort="0" lower="-0.5" upper="0.5" velocity="0"/>
  </joint>
  <link name="neck">
    <visual>
      <origin rpy="0 0 0" xyz="0 0 0"/>
      <geometry>
        <mesh filename="package://moria_description/meshes/neck.STL"/>
      </geometry>
      <material name="cyan">
        <color rgba="0.3137 0.6941 0.7843 1"/>
      </material>
    </visual>
    <collision>
      <origin rpy="0 0 0" xyz="0 0 0"/>
      <geometry>
        <mesh filename="package://moria_description/meshes/neck.STL"/>
      </geometry>
    </collision>
    <inertial>
      <origin rpy="0 0 0" xyz="0 0 0"/>
      <mass value="0.046"/>
      <inertia ixx="0.00001" ixy="0.0" ixz="0.0" iyy="0.00001" iyz="0.0" izz="0.00001"/>
    </inertial>
  </link>
  <joint name="head_joint" type="revolute">
    <parent link="neck"/>
    <child link="head"/>
    <origin rpy="1.5708 0 1.5708" xyz="0.0224 0.004 0.0403"/>
    <axis xyz="0 0 1"/>
    <limit effort="0" lower="-0.2" upper="0.2" velocity="0"/>
  </joint>
  <link name="head">
    <visual>
      <origin rpy="0 0 0" xyz="0 0 0"/>
      <geometry>
        <mesh filename="package://moria_description/meshes/head.STL"/>
      </geometry>
      <material name="cyan">
        <color rgba="0.3137 0.6941 0.7843 1"/>
      </material>
    </visual>
    <collision>
      <origin rpy="0 0 0" xyz="0 0 0"/>
      <geometry>
        <mesh filename="package://moria_description/meshes/head.STL"/>
      </geometry>
    </collision>
    <inertial>
      <origin rpy="0 0 0" xyz="0 0 0"/>
      <mass value="0.7694"/>
      <inertia ixx="0.0045" ixy="0.00005" ixz="0.0" iyy="0.0029" iyz="0.0" izz="0.0023"/>
    </inertial>
  </link>
  <!-- LIDAR-->
  <joint name="lidar_joint" type="fixed">
    <parent link="leg"/>
    <child link="lidar"/>
    <origin rpy="0 0 0" xyz="0.1335 0.0005 0.0156"/>
  </joint>
  <link name="lidar">
    <visual>
      <origin rpy="0 0 0" xyz="0 0 0"/>
      <geometry>
        <mesh filename="package://moria_description/meshes/lidar.STL"/>
      </geometry>
      <material name="cyan">
        <color rgba="0.3137 0.6941 0.7843 1"/>
      </material>
    </visual>
    <collision>
      <origin rpy="0 0 0" xyz="0 0 0"/>
      <geometry>
        <mesh filename="package://moria_description/meshes/lidar.STL"/>
      </geometry>
    </collision>
    <inertial>
      <origin rpy="0 0 0" xyz="0 0 0"/>
      <mass value="1.33"/>
      <inertia ixx="0.00061" ixy="0.0" ixz="-0.00015" iyy="0.00097" iyz="0.0" izz="0.00110"/>
    </inertial>
  </link>
  <!-- CAMERA-->
  <joint name="camera_joint" type="fixed">
    <parent link="body"/>
    <child link="camera"/>
    <origin rpy="0 0 0" xyz="0.0839 0.0004 0.507"/>
  </joint>
  <link name="camera">
    <visual>
      <origin rpy="0 0 0" xyz="0 0 0"/>
      <geometry>
        <mesh filename="package://moria_description/meshes/camera.STL"/>
      </geometry>
      <material name="cyan">
        <color rgba="0.3137 0.6941 0.7843 1"/>
      </material>
    </visual>
    <collision>
      <origin rpy="0 0 0" xyz="0 0 0"/>
      <geometry>
        <mesh filename="package://moria_description/meshes/camera.STL"/>
      </geometry>
    </collision>
    <inertial>
      <origin rpy="0 0 0" xyz="0 0 0"/>
      <mass value="0.10791"/>
      <inertia ixx="0.00007" ixy="0.0" ixz="0.0" iyy="0.000008" iyz="0.0" izz="0.00007"/>
    </inertial>
  </link>
  <!-- ......:::::: RIGHT ARM ::::::...... -->
  <!-- RIGHT SHOULDER-->
  <joint name="right_shoulder_rad_joint" type="continuous">
    <parent link="body"/>
    <child link="right_shoulder_rad"/>
    <origin rpy="-1.5708 0 0" xyz="0 -0.1556 0.505"/>
    <axis xyz="0 0 1"/>
  </joint>
  <link name="right_shoulder_rad">
    <visual>
      <origin rpy="0 0 0" xyz="0 0 0"/>
      <geometry>
        <mesh filename="package://moria_description/meshes/right_shoulder_rad.STL"/>
      </geometry>
      <material name="">
        <color rgba="0.3137 0.6941 0.7843 1"/>
      </material>
    </visual>
    <collision>
      <origin rpy="0 0 0" xyz="0 0 0"/>
      <geometry>
        <mesh filename="package://moria_description/meshes/right_shoulder_rad.STL"/>
      </geometry>
    </collision>
    <inertial>
      <origin rpy="0 0 0" xyz="0 0 0"/>
      <mass value="0.1128"/>
      <inertia ixx="0.00007" ixy="0.0" ixz="0.0" iyy="0.00006" iyz="0.0" izz="0.00004"/>
    </inertial>
  </link>
</robot>
