<?xml version="1.0"?>
<robot xmlns:xacro="http://www.ros.org/wiki/xacro">

    <!-- left ARM-->
    <joint name="left_shoulder_rad_joint" type="revolute">
        <parent link="body"/>
        <child link="left_shoulder_rad"/>
        <origin xyz="0 0.1585 0.503" rpy="-1.5708 0 0"/>
        <axis xyz="0 0 -1"/>
        <limit 
            lower="-1"
            upper="2.5"
            effort="3.7"
            velocity="0.22"/>
    </joint>

    <link name="left_shoulder_rad">
        <visual>
            <origin xyz="0 0 0" rpy="0 0 0"/>
            <geometry>
                <mesh 
                    filename="file://$(find moria_description)/meshes/left_shoulder_rad.STL"/>
            </geometry>
            <material name="blue">
                <color rgba="0.0667 0.2431 0.4078 1"/>
            </material>
        </visual>

        <collision>
            <origin xyz="0 0 0" rpy="0 0 0"/>
            <geometry>
                <mesh filename="file://$(find moria_description)/meshes/left_shoulder_rad.STL"/>
            </geometry>
        </collision>

        <inertial>
            <origin xyz="0 0 0" rpy="0 0 0"/>
            <mass value="${shoulder_rad_mass}"/>
            <inertia 
                ixx="7.00E-05" ixy="3.08E-10" ixz="8.62E-07"
                iyy="6.07E-05" iyz="-7.16E-07"
                izz="3.73E-05" />
        </inertial>
    </link>




    <joint name="left_shoulder_joint" type="revolute">
        <parent link="left_shoulder_rad"/>
        <child link="left_shoulder"/>
        <origin xyz="0.0252 -0.004 0.059" rpy="0 -1.5708 3.14"/>
        <axis xyz="0 0 1"/>
        <limit 
            lower="-1"
            upper="2.5"
            effort="3.7"
            velocity="0.22"/>
    </joint>

    <link name="left_shoulder">
        <visual>
            <origin xyz="0 0 0" rpy="0 0 0"/>
            <geometry>
                <mesh filename="file://$(find moria_description)/meshes/left_shoulder.STL"/>
            </geometry>
            <material name="cyan">
                <color rgba="0.3137 0.6941 0.7843 1"/>
            </material>
        </visual>
        <collision>
            <origin xyz="0 0 0" rpy="0 0 0"/>
            <geometry>
                <mesh filename="file://$(find moria_description)/meshes/left_shoulder.STL"/>
            </geometry>
        </collision>
        <inertial>
            <origin xyz="0 0 0" rpy="0 0 0"/>
            <mass value="${shoulder_mass}"/>
            <inertia 
                ixx="0.00010" ixy="-5.82E-06" ixz="-3.09E-07"
                iyy="7.10E-05" iyz="-3.22E-06"
                izz="0.00011" />
        </inertial>
    </link>




    <!-- UPPER ARM-->
    <joint name="left_upper_arm_joint" type="revolute">
        <parent link="left_shoulder"/>
        <child link="left_upper_arm"/>
        <origin xyz="0 -0.0855 -0.0255" rpy="-1.5708 -1.5708 0"/>
        <axis xyz="0 0 1"/>
        <limit 
            lower="-1"
            upper="2.5"
            effort="3.7"
            velocity="0.22"/>
    </joint>

    <link name="left_upper_arm">
        <visual>
            <origin xyz="0 0 0" rpy="0 0 0"/>
            <geometry>
                <mesh filename="file://$(find moria_description)/meshes/left_upper_arm.STL"/>
            </geometry>
            <material name="blue">
                <color rgba="0.0667 0.2431 0.4078 1"/>
            </material>
        </visual>
        <collision>
            <origin xyz="0 0 0" rpy="0 0 0"/>
            <geometry>
                <mesh filename="file://$(find moria_description)/meshes/left_upper_arm.STL"/>
            </geometry>
        </collision>
        <inertial>
            <origin xyz="0 0 0" rpy="0 0 0"/>
            <mass value="${upper_arm_mass}"/>
            <inertia 
                ixx="0.00022" ixy="-4.98E-10" ixz="-5.62E-07"
                iyy="0.00021" iyz="-1.80E-07"
                izz="5.01E-05" />
        </inertial>
    </link>




    <!-- left ELBOW-->
    <joint name="left_elbow_joint" type="revolute">
        <parent link="left_upper_arm"/>
        <child link="left_elbow"/>
        <origin xyz="0 0.0228 -0.1432" rpy="-1.5708 0 0"/>
        <axis xyz="0 0 -1"/>
        <limit 
            lower="-1"
            upper="2.5"
            effort="3.7"
            velocity="0.22"/>
    </joint>

    <link name="left_elbow">
        <visual>
            <origin xyz="0 0 0" rpy="0 0 0"/>
            <geometry>
                <mesh filename="file://$(find moria_description)/meshes/left_elbow.STL"/>
            </geometry>
            <material name="cyan">
                <color rgba="0.3137 0.6941 0.7843 1"/>
            </material>
        </visual>
        <collision>
            <origin xyz="0 0 0" rpy="0 0 0"/>
            <geometry>
                <mesh filename="file://$(find moria_description)/meshes/left_elbow.STL"/>
            </geometry>
        </collision>
        <inertial>
            <origin xyz="0 0 0" rpy="0 0 0"/>
            <mass value="${elbow_mass}"/>
            <inertia 
                ixx="9.91E-05" ixy="-1.49E-06" ixz="2.12E-06"
                iyy="5.33E-05" iyz="4.53E-06"
                izz="8.43E-05" />
        </inertial>
    </link>




    <!-- left LOWER ARM-->
    <joint name="left_lower_arm_joint" type="revolute">
        <parent link="left_elbow"/>
        <child link="left_lower_arm"/>
        <origin xyz="0 0.0846 -0.0232" rpy="1.5708 -0.050433 0"/>
        <axis xyz="0 0 1"/>
        <limit 
            lower="-1"
            upper="2.5"
            effort="3.7"
            velocity="0.22"/>
    </joint>

    <link name="left_lower_arm">
        <visual>
            <origin xyz="0 0 0" rpy="0 0 0"/>
            <geometry>
                <mesh filename="file://$(find moria_description)/meshes/left_lower_arm.STL"/>
            </geometry>
            <material name="blue">
                <color rgba="0.0667 0.2431 0.4078 1"/>
            </material>
        </visual>
        <collision>
            <origin xyz="0 0 0" rpy="0 0 0"/>
            <geometry>
                <mesh filename="file://$(find moria_description)/meshes/left_lower_arm.STL"/>
            </geometry>
        </collision>
        <inertial>
            <origin xyz="0 0 0" rpy="0 0 0"/>
            <mass value="${lower_arm_mass}"/>
            <inertia 
                ixx="0.00032" ixy="-7.01E-07" ixz="3.96E-07"
                iyy="0.00032" iyz="1.98E-06"
                izz="0.00012" />
        </inertial>
    </link>




    <!-- left THUMB-->
    <joint name="left_00_joint" type="revolute">
        <parent link="left_lower_arm"/>
        <child link="left_00"/>
        <origin xyz="0.0286 0.001 -0.1877" rpy="-2.8828 0.29907 -2.4097"/>
        <axis xyz="0 0 1"/>
        <limit 
            lower="-1"
            upper="2.5"
            effort="3.7"
            velocity="0.22"/>
    </joint>

    <link name="left_00">
        <visual>
            <origin xyz="0 0 0" rpy="0 0 0"/>
            <geometry>
                <mesh filename="file://$(find moria_description)/meshes/left_00.STL"/>
            </geometry>
            <material name="cyan">
                <color rgba="0.3137 0.6941 0.7843 1"/>
            </material>
        </visual>
        <collision>
            <origin xyz="0 0 0" rpy="0 0 0"/>
            <geometry>
                <mesh filename="file://$(find moria_description)/meshes/left_00.STL"/>
            </geometry>
        </collision>
        <inertial>
            <origin xyz="0 0 0" rpy="0 0 0"/>
            <mass value="0.005"/>
            <inertia 
                ixx="3E-07" ixy="0.0" ixz="0.0"
                iyy="2E-07" iyz="0.0"
                izz="2E-07" />
        </inertial>
    </link>

    <joint name="left_01_joint" type="revolute">
        <parent link="left_00"/>
        <child link="left_01"/>
        <origin xyz="0.0015 -0.0223 0.0062" rpy="1.0472 -0.31649 -1.5708"/>
        <axis xyz="0 0 1"/>
        <limit 
            lower="-1"
            upper="2.5"
            effort="3.7"
            velocity="0.22"/>
    </joint>

    <link name="left_01">
        <visual>
            <origin xyz="0 0 0" rpy="0 0 0"/>
            <geometry>
                <mesh filename="file://$(find moria_description)/meshes/left_01.STL"/>
            </geometry>
            <material name="cyan">
                <color rgba="0.3137 0.6941 0.7843 1"/>
            </material>
        </visual>
        <collision>
            <origin xyz="0 0 0" rpy="0 0 0"/>
            <geometry>
                <mesh filename="file://$(find moria_description)/meshes/left_01.STL"/>
            </geometry>
        </collision>
        <inertial>
            <origin xyz="0 0 0" rpy="0 0 0"/>
            <mass value="0.002"/>
            <inertia 
                ixx="1E-07" ixy="0.0" ixz="0.0"
                iyy="1E-07" iyz="0.0"
                izz="8E-08" />
        </inertial>
    </link>

    <joint name="left_02_joint" type="revolute">
        <parent link="left_01"/>
        <child link="left_02"/>
        <origin xyz="0.01815 0.01722 0" rpy="-0.0802 0.5284 2.1259"/>
        <axis xyz="0 0 1"/>
        <limit 
            lower="-1"
            upper="2.5"
            effort="3.7"
            velocity="0.22"/>
    </joint>

    <link name="left_02">
        <visual>
            <origin xyz="0 0 0" rpy="0 0 0"/>
            <geometry>
                <mesh filename="file://$(find moria_description)/meshes/left_02.STL"/>
            </geometry>
            <material name="cyan">
                <color rgba="0.3137 0.6941 0.7843 1"/>
            </material>
        </visual>
        <collision>
            <origin xyz="0 0 0" rpy="0 0 0"/>
            <geometry>
                <mesh filename="file://$(find moria_description)/meshes/left_02.STL"/>
            </geometry>
        </collision>
        <inertial>
            <origin xyz="0 0 0" rpy="0 0 0"/>
            <mass value="0.002"/>
            <inertia 
                ixx="6E-08" ixy="0.0" ixz="0.0"
                iyy="6E-08" iyz="0.0"
                izz="7E-08" />
        </inertial>
    </link>




    <!--left INDEX-->
    <joint name="left_10_joint" type="revolute">
        <parent link="left_lower_arm"/>
        <child link="left_10"/>
        <origin xyz="0.0267 0.0010 -0.2477" rpy="-1.5708 0 -1.5708"/>
        <axis xyz="0 0 -1"/>
        <limit 
            lower="-1"
            upper="2.5"
            effort="3.7"
            velocity="0.22"/>
    </joint>

    <link name="left_10">
        <visual>
            <origin xyz="0 0 0" rpy="0 0 0"/>
            <geometry>
                <mesh filename="file://$(find moria_description)/meshes/left_10.STL"/>
            </geometry>
            <material name="cyan">
                <color rgba="0.3137 0.6941 0.7843 1"/>
            </material>
        </visual>
        <collision>
            <origin xyz="0 0 0" rpy="0 0 0"/>
            <geometry>
                <mesh filename="file://$(find moria_description)/meshes/left_10.STL"/>
            </geometry>
        </collision>
        <inertial>
            <origin xyz="0 0 0" rpy="0 0 0"/>
            <mass value="0.002"/>
            <inertia 
                ixx="8E-08" ixy="0.0" ixz="0.0"
                iyy="6E-08" iyz="0.0"
                izz="6E-08" />
        </inertial>
    </link>

    <joint name="left_11_joint" type="revolute">
        <parent link="left_10"/>
        <child link="left_11"/>
        <origin xyz="0 0.024 0" rpy="0 0 0"/>
        <axis xyz="0 0 -1"/>
        <limit 
            lower="-1"
            upper="2.5"
            effort="3.7"
            velocity="0.22"/>
    </joint>

    <link name="left_11">
        <visual>
            <origin xyz="0 0 0" rpy="0 0 0"/>
            <geometry>
                <mesh filename="file://$(find moria_description)/meshes/left_11.STL"/>
            </geometry>
            <material name="cyan">
                <color rgba="0.3137 0.6941 0.7843 1"/>
            </material>
        </visual>
        <collision>
            <origin xyz="0 0 0" rpy="0 0 0"/>
            <geometry>
                <mesh filename="file://$(find moria_description)/meshes/left_11.STL"/>
            </geometry>
        </collision>
        <inertial>
            <origin xyz="0 0 0" rpy="0 0 0"/>
            <mass value="0.002"/>
            <inertia 
                ixx="6E-08" ixy="0.0" ixz="0.0"
                iyy="5E-08" iyz="0.0"
                izz="6E-08" />
        </inertial>
    </link>

    <joint name="left_12_joint" type="revolute">
        <parent link="left_11"/>
        <child link="left_12"/>
        <origin xyz="0 0.0210 0" rpy="0 0 0.12237"/>
        <axis xyz="0 0 -1"/>
        <limit 
            lower="-1"
            upper="2.5"
            effort="3.7"
            velocity="0.22"/>
    </joint>

    <link name="left_12">
        <visual>
            <origin xyz="0 0 0" rpy="0 0 0"/>
            <geometry>
                <mesh filename="file://$(find moria_description)/meshes/left_12.STL"/>
            </geometry>
            <material name="cyan">
                <color rgba="0.3137 0.6941 0.7843 1"/>
            </material>
        </visual>
        <collision>
            <origin xyz="0 0 0" rpy="0 0 0"/>
            <geometry>
                <mesh filename="file://$(find moria_description)/meshes/left_12.STL"/>
            </geometry>
        </collision>
        <inertial>
            <origin xyz="0 0 0" rpy="0 0 0"/>
            <mass value="0.002"/>
            <inertia 
                ixx="4E-08" ixy="0.0" ixz="0.0"
                iyy="3E-08" iyz="0.0"
                izz="4E-08" />
        </inertial>
    </link>




    <!--left MIDDLE-->
    <joint name="left_20_joint" type="revolute">
        <parent link="left_lower_arm"/>
        <child link="left_20"/>
        <origin xyz="0.0092 0.0010 -0.2477" rpy="-1.5708 0 -1.5708"/>
        <axis xyz="0 0 -1"/>
        <limit 
            lower="-1"
            upper="2.5"
            effort="3.7"
            velocity="0.22"/>
    </joint>

    <link name="left_20">
        <visual>
            <origin xyz="0 0 0" rpy="0 0 0"/>
            <geometry>
                <mesh filename="file://$(find moria_description)/meshes/left_20.STL"/>
            </geometry>
            <material name="cyan">
                <color rgba="0.3137 0.6941 0.7843 1"/>
            </material>
        </visual>
        <collision>
            <origin xyz="0 0 0" rpy="0 0 0"/>
            <geometry>
                <mesh filename="file://$(find moria_description)/meshes/left_20.STL"/>
            </geometry>
        </collision>
        <inertial>
            <origin xyz="0 0 0" rpy="0 0 0"/>
            <mass value="0.003"/>
            <inertia 
                ixx="1E-07" ixy="0.0" ixz="0.0"
                iyy="1E-07" iyz="0.0"
                izz="1E-07" />
        </inertial>
    </link>

    <joint name="left_21_joint" type="revolute">
        <parent link="left_20"/>
        <child link="left_21"/>
        <origin xyz="-0.0004 0.0265 0" rpy="0 0.0504 0"/>
        <axis xyz="0 0 -1"/>
        <limit 
            lower="-1"
            upper="2.5"
            effort="3.7"
            velocity="0.22"/>
    </joint>

    <link name="left_21">
        <visual>
            <origin xyz="0 0 0" rpy="0 0 0"/>
            <geometry>
                <mesh filename="file://$(find moria_description)/meshes/left_21.STL"/>
            </geometry>
            <material name="cyan">
                <color rgba="0.3137 0.6941 0.7843 1"/>
            </material>
        </visual>
        <collision>
            <origin xyz="0 0 0" rpy="0 0 0"/>
            <geometry>
                <mesh filename="file://$(find moria_description)/meshes/left_21.STL"/>
            </geometry>
        </collision>
        <inertial>
            <origin xyz="0 0 0" rpy="0 0 0"/>
            <mass value="0.002"/>
            <inertia 
                ixx="6E-08" ixy="0.0" ixz="0.0"
                iyy="6E-08" iyz="0.0"
                izz="8E-08" />
        </inertial>
    </link>

    <joint name="left_22_joint" type="revolute">
        <parent link="left_21"/>
        <child link="left_22"/>
        <origin xyz="-0.0002 0.0229 -0.0002" rpy="0 -0.050433 0"/>
        <axis xyz="0 0 -1"/>
        <limit 
            lower="-1"
            upper="2.5"
            effort="3.7"
            velocity="0.22"/>
    </joint>

    <link name="left_22">
        <visual>
            <origin xyz="0 0 0" rpy="0 0 0"/>
            <geometry>
                <mesh filename="file://$(find moria_description)/meshes/left_22.STL"/>
            </geometry>
            <material name="cyan">
                <color rgba="0.3137 0.6941 0.7843 1"/>
            </material>
        </visual>
        <collision>
            <origin xyz="0 0 0" rpy="0 0 0"/>
            <geometry>
                <mesh filename="file://$(find moria_description)/meshes/left_22.STL"/>
            </geometry>
        </collision>
        <inertial>
            <origin xyz="0 0 0" rpy="0 0 0"/>
            <mass value="0.002"/>
            <inertia 
                ixx="6E-08" ixy="0.0" ixz="0.0"
                iyy="6E-08" iyz="0.0"
                izz="8E-08" />
        </inertial>
    </link>




    <!--left RING-->
    <joint name="left_30_joint" type="revolute">
        <parent link="left_lower_arm"/>
        <child link="left_30"/>
        <origin xyz="-0.0082 0.0010 -0.2477" rpy="-1.5708 0 -1.5708"/>
        <axis xyz="0 0 -1"/>
        <limit 
            lower="-1"
            upper="2.5"
            effort="3.7"
            velocity="0.22"/>
    </joint>

    <link name="left_30">
        <visual>
            <origin xyz="0 0 0" rpy="0 0 0"/>
            <geometry>
                <mesh filename="file://$(find moria_description)/meshes/left_30.STL"/>
            </geometry>
            <material name="cyan">
                <color rgba="0.3137 0.6941 0.7843 1"/>
            </material>
        </visual>
        <collision>
            <origin xyz="0 0 0" rpy="0 0 0"/>
            <geometry>
                <mesh filename="file://$(find moria_description)/meshes/left_30.STL"/>
            </geometry>
        </collision>
        <inertial>
            <origin xyz="0 0 0" rpy="0 0 0"/>
            <mass value="0.002"/>
            <inertia 
                ixx="8E-08" ixy="0.0" ixz="0.0"
                iyy="6E-08" iyz="0.0"
                izz="7E-08" />
        </inertial>
    </link>

    <joint name="left_31_joint" type="revolute">
        <parent link="left_30"/>
        <child link="left_31"/>
        <origin xyz="-0.0002 0.0239 0" rpy="0 0 0"/>
        <axis xyz="0 0 -1"/>
        <limit 
            lower="-1"
            upper="2.5"
            effort="3.7"
            velocity="0.22"/>
    </joint>

    <link name="left_31">
        <visual>
            <origin xyz="0 0 0" rpy="0 0 0"/>
            <geometry>
                <mesh filename="file://$(find moria_description)/meshes/left_31.STL"/>
            </geometry>
            <material name="cyan">
                <color rgba="0.3137 0.6941 0.7843 1"/>
            </material>
        </visual>
        <collision>
            <origin xyz="0 0 0" rpy="0 0 0"/>
            <geometry>
                <mesh filename="file://$(find moria_description)/meshes/left_31.STL"/>
            </geometry>
        </collision>
        <inertial>
            <origin xyz="0 0 0" rpy="0 0 0"/>
            <mass value="0.002"/>
            <inertia 
                ixx="6E-08" ixy="0.0" ixz="0.0"
                iyy="5E-08" iyz="0.0"
                izz="6E-08" />
        </inertial>
    </link>

    <joint name="left_32_joint" type="revolute">
        <parent link="left_31"/>
        <child link="left_32"/>
        <origin xyz="-0.0002 0.0210 0" rpy="0 0 0"/>
        <axis xyz="0 0 -1"/>
        <limit 
            lower="-1"
            upper="2.5"
            effort="3.7"
            velocity="0.22"/>
    </joint>

    <link name="left_32">
        <visual>
            <origin xyz="0 0 0" rpy="0 0 0"/>
            <geometry>
                <mesh filename="file://$(find moria_description)/meshes/left_32.STL"/>
            </geometry>
            <material name="cyan">
                <color rgba="0.3137 0.6941 0.7843 1"/>
            </material>
        </visual>
        <collision>
            <origin xyz="0 0 0" rpy="0 0 0"/>
            <geometry>
                <mesh filename="file://$(find moria_description)/meshes/left_32.STL"/>
            </geometry>
        </collision>
        <inertial>
            <origin xyz="0 0 0" rpy="0 0 0"/>
            <mass value="0.002"/>
            <inertia 
                ixx="4E-08" ixy="0.0" ixz="0.0"
                iyy="3E-08" iyz="0.0"
                izz="4E-08" />
        </inertial>
    </link>




    <!-- left PINKY-->
    <joint name="left_40_joint" type="revolute">
        <parent link="left_lower_arm"/>
        <child link="left_40"/>
        <origin xyz="-0.0257 0.0010 -0.2477" rpy="-1.5708 0 -1.5708"/>
        <axis xyz="0 0 -1"/>
        <limit 
            lower="-1"
            upper="2.5"
            effort="3.7"
            velocity="0.22"/>
    </joint>

    <link name="left_40">
        <visual>
            <origin xyz="0 0 0" rpy="0 0 0"/>
            <geometry>
                <mesh filename="file://$(find moria_description)/meshes/left_40.STL"/>
            </geometry>
            <material name="cyan">
                <color rgba="0.3137 0.6941 0.7843 1"/>
            </material>
        </visual>
        <collision>
            <origin xyz="0 0 0" rpy="0 0 0"/>
            <geometry>
                <mesh filename="file://$(find moria_description)/meshes/left_40.STL"/>
            </geometry>
        </collision>
        <inertial>
            <origin xyz="0 0 0" rpy="0 0 0"/>
            <mass value="0.002"/>
            <inertia 
                ixx="6E-08" ixy="0.0" ixz="0.0"
                iyy="4E-08" iyz="0.0"
                izz="4E-08" />
        </inertial>
    </link>

    <joint name="left_41_joint" type="revolute">
        <parent link="left_40"/>
        <child link="left_41"/>
        <origin xyz="0.0008 0.0231 0" rpy="0 0 0"/>
        <axis xyz="0 0 -1"/>
        <limit 
            lower="-1"
            upper="2.5"
            effort="3.7"
            velocity="0.22"/>
    </joint>

    <link name="left_41">
        <visual>
            <origin xyz="0 0 0" rpy="0 0 0"/>
            <geometry>
                <mesh filename="file://$(find moria_description)/meshes/left_41.STL"/>
            </geometry>
            <material name="cyan">
                <color rgba="0.3137 0.6941 0.7843 1"/>
            </material>
        </visual>
        <collision>
            <origin xyz="0 0 0" rpy="0 0 0"/>
            <geometry>
                <mesh filename="file://$(find moria_description)/meshes/left_41.STL"/>
            </geometry>
        </collision>
        <inertial>
            <origin xyz="0 0 0" rpy="0 0 0"/>
            <mass value="0.002"/>
            <inertia 
                ixx="3E-08" ixy="0.0" ixz="0.0"
                iyy="3E-08" iyz="0.0"
                izz="3E-08" />
        </inertial>
    </link>

    <joint name="left_42_joint" type="revolute">
        <parent link="left_41"/>
        <child link="left_42"/>
        <origin xyz="-0.00088 0.0183 0" rpy="0 0 0.0148"/>
        <axis xyz="0 0 -1"/>
        <limit 
            lower="-1"
            upper="2.5"
            effort="3.7"
            velocity="0.22"/>
    </joint>

    <link name="left_42">
        <visual>
            <origin xyz="0 0 0" rpy="0 0 0"/>
            <geometry>
                <mesh filename="file://$(find moria_description)/meshes/left_42.STL"/>
            </geometry>
            <material name="cyan">
                <color rgba="0.3137 0.6941 0.7843 1"/>
            </material>
        </visual>
        <collision>
            <origin xyz="0 0 0" rpy="0 0 0"/>
            <geometry>
                <mesh filename="file://$(find moria_description)/meshes/left_42.STL"/>
            </geometry>
        </collision>
        <inertial>
            <origin xyz="0 0 0" rpy="0 0 0"/>
            <mass value="0.002"/>
            <inertia 
                ixx="1E-08" ixy="0.0" ixz="0.0"
                iyy="1E-08" iyz="0.0"
                izz="1E-08" />
        </inertial>
    </link>
</robot>
