<?xml version="1.0"?>
<robot xmlns:xacro="http://www.ros.org/wiki/xacro" name="moria">

    <xacro:property name="base_mass" value="15.0"/>
	<xacro:property name="leg_mass" value="5.0"/>
	<xacro:property name="body_mass" value="3.0"/>
	<xacro:property name="head_mass" value="1.25"/>
    <xacro:property name="lower_arm_mass" value="0.882"/>
    <xacro:property name="elbow_mass" value="0.176"/>
    <xacro:property name="upper_arm_mass" value="0.2"/>
    <xacro:property name="shoulder_mass" value="0.223"/>
    <xacro:property name="shoulder_rad_mass" value="0.224"/>

	<joint name="base_joint" type="fixed">
		<parent link="base_footprint"/>
		<child link="base_link"/>
		<origin xyz="0 0 0" rpy="0 0 0"/>
	</joint>

	<link name="base_footprint"></link>


    

    <link name="base_link">
        <visual>
            <origin xyz="0 0 0" rpy="0 0 0"/>
            <geometry>
                <mesh filename="file://$(find moria_description)/meshes/base_link.STL"/>
            </geometry>
            <material name="blue">
                <color rgba="0.0667 0.2431 0.4078 1"/>
            </material>
        </visual>
        <collision>
            <origin xyz="0 0 0" rpy="0 0 0"/>
            <geometry>
                <mesh filename="file://$(find moria_description)/meshes/base_link.STL"/>
            </geometry>
        </collision>
        <inertial>
            <origin xyz="0 0 0" rpy="0 0 0"/>
            <mass value="${base_mass}"/>
            <inertia 
                ixx="0.04490" ixy="8.82E-06" ixz="5.15E-05"
                iyy="0.06578" iyz="-1.21E-05"
                izz="0.09095" />
        </inertial>
    </link>




    <!-- FRONT WHEEL -->
    <joint name="front_base_joint" type="fixed">
        <origin xyz="0.3025 0 -0.011" rpy="0 0 0"/>
        <parent link="base_link"/>
        <child link="front_base"/>
    </joint>

    <link name="front_base">
        <visual>
            <origin xyz="0 0 0" rpy="0 0 0"/>
            <geometry>
                <mesh filename="file://$(find moria_description)/meshes/front_base.STL"/>
            </geometry>
            <material name="blue">
                <color rgba="0.0667 0.2431 0.4078 1"/>
            </material>
        </visual>
        <collision>
            <origin xyz="0 0 0" rpy="0 0 0"/>
            <geometry>
                <mesh filename="file://$(find moria_description)/meshes/front_base.STL"/>
            </geometry>
        </collision>
        <inertial>
            <origin xyz="0 0 0" rpy="0 0 0"/>
            <mass value="0.003"/>
            <inertia 
                ixx="1.48E-07" ixy="0.00" ixz="0.00"
                iyy="1.48E-07" iyz="0.00"
                izz="2.95E-07" />
        </inertial>
    </link>


    <joint name="front_radial_joint" type="continuous">
        <parent link="front_base"/>
        <child link="front_radial"/>
        <origin xyz="0 0 0" rpy="0 0 0"/>
        <axis xyz="0 0 1"/>
    </joint>

    <link name="front_radial">
        <visual>
            <origin xyz="0 0 0" rpy="0 0 0"/>
            <geometry>
                <mesh filename="file://$(find moria_description)/meshes/front_rad.STL"/>
            </geometry>
            <material name="blue">
                <color rgba="0.0667 0.2431 0.4078 1"/>
            </material>
        </visual>
        <collision>
            <origin xyz="0 0 0" rpy="0 0 0"/>
            <geometry>
                <mesh filename="file://$(find moria_description)/meshes/front_rad.STL"/>
            </geometry>
        </collision>
        <inertial>
            <origin xyz="0 0 0" rpy="0 0 0"/>
            <mass value="0.01"/>
            <inertia 
                ixx="1.95E-06" ixy="-1.75E-11" ixz="4.62E-07"
                iyy="2.27E-06" iyz="0.00"
                izz="2.70E-06" />
        </inertial>
    </link>


    <joint name="front_wheel_joint" type="continuous">
        <parent link="front_radial"/>
        <child link="front_wheel"/>
        <origin xyz="0.0223 0 -0.0335" rpy="1.5708 0 0"/>
        <axis xyz="0 0 -1"/>
    </joint>

    <link name="front_wheel">
        <visual>
            <origin xyz="0 0 0" rpy="0 0 0"/>
            <geometry>
                <mesh filename="file://$(find moria_description)/meshes/front_wheel.STL"/>
            </geometry>
            <material name="cyan">
                <color rgba="0.3137 0.6941 0.7843 1"/>
            </material>
        </visual>
        <collision>
            <origin xyz="0 0 0" rpy="0 0 0"/>
            <geometry>
                <mesh filename="file://$(find moria_description)/meshes/front_wheel.STL"/>
            </geometry>
        </collision>
        <inertial>
            <origin xyz="0 0 0" rpy="0 0 0"/>
            <mass value="0.006"/>
            <inertia 
                ixx="1.08E-06" ixy="0.0" ixz="0.0"
                iyy="1.08E-06" iyz="0.0"
                izz="1.73E-06" />
        </inertial>
    </link>

    


    <!-- RIGHT WHEEL-->
    <joint name="right_motor_joint" type="fixed">
        <parent link="base_link"/>
        <child link="right_motor"/>
        <origin xyz="0.0 -0.1145 -0.03" rpy="0 0 0"/>
    </joint>

    <link name="right_motor">
        <visual>
            <origin xyz="0 0 0" rpy="0 0 0"/>
            <geometry>
                <mesh filename="file://$(find moria_description)/meshes/right_motor.STL"/>
            </geometry>
            <material name="blue">
                <color rgba="0.0667 0.2431 0.4078 1"/>
            </material>
        </visual>
        <collision>
            <origin xyz="0 0 0" rpy="0 0 0"/>
            <geometry>
                <mesh filename="file://$(find moria_description)/meshes/right_motor.STL"/>
            </geometry>
        </collision>
        <inertial>
            <origin xyz="0 0 0" rpy="0 0 0"/>
            <mass value="0.11"/>
            <inertia 
                ixx="2.72E-05" ixy="-1.08E-06" ixz="2.27E-08"
                iyy="5.03E-05" iyz="3.21E-08"
                izz="5.52E-05" />
        </inertial>
    </link>


    <joint name="right_wheel_joint" type="continuous">
        <parent link="right_motor"/>
        <child link="right_wheel"/>
        <origin xyz="0 -0.0795 0" rpy="1.5708 0 0"/>
        <axis xyz="0 0 -1"/>
    </joint>

    <link name="right_wheel">
        <visual>
            <origin xyz="0 0 0" rpy="0 0 0"/>
            <geometry>
                <mesh filename="file://$(find moria_description)/meshes/right_wheel.STL"/>
            </geometry>
            <material name="cyan">
                <color rgba="0.3137 0.6941 0.7843 1"/>
            </material>
        </visual>
        <collision>
            <origin xyz="0 0 0" rpy="0 0 0"/>
            <geometry>
                <mesh filename="file://$(find moria_description)/meshes/right_wheel.STL"/>
            </geometry>
        </collision>
        <inertial>
            <origin xyz="0 0 0" rpy="0 0 0"/>
            <mass value="0.09111"/>
            <inertia 
                ixx="9.34E-05" ixy="0.0" ixz="0.0"
                iyy="9.34E-05" iyz="0.0"
                izz="0.00015" />
        </inertial>
    </link>




    <!-- LEFT WHEEL-->
    <joint name="left_motor_joint" type="fixed">
        <parent link="base_link"/>
        <child link="left_motor"/>
        <origin xyz="0 0.1145 -0.0300" rpy="0 0 -3.1416"/>
    </joint>

    <link name="left_motor">
        <visual>
            <origin xyz="0 0 0" rpy="0 0 0"/>
            <geometry>
                <mesh filename="file://$(find moria_description)/meshes/left_motor.STL"/>
            </geometry>
            <material name="blue">
                <color rgba="0.0667 0.2431 0.4078 1"/>
            </material>
        </visual>
        <collision>
            <origin xyz="0 0 0" rpy="0 0 0"/>
            <geometry>
                <mesh filename="file://$(find moria_description)/meshes/left_motor.STL"/>
            </geometry>
        </collision>
        <inertial>
            <origin xyz="0 0 0" rpy="0 0 0"/>
            <mass value="0.11"/>
            <inertia 
                ixx="2.72E-05" ixy="1.08E-06" ixz="-1.98E-08"
                iyy="5.02E-05" iyz="3.70E-08"
                izz="5.52E-05" />
        </inertial>
    </link>


    <joint name="left_wheel_joint" type="continuous">
        <parent link="left_motor"/>
        <child link="left_wheel"/>
        <origin xyz="0 -0.0795 0" rpy="1.5708 0 0"/>
        <axis xyz="0 0 1"/>
    </joint>

    <link name="left_wheel">
        <visual>
            <origin xyz="0 0 0" rpy="0 0 0"/>
            <geometry>
                <mesh filename="file://$(find moria_description)/meshes/left_wheel.STL"/>
            </geometry>
            <material name="cyan">
                <color rgba="0.3137 0.6941 0.7843 1"/>
            </material>
        </visual>
        <collision>
            <origin xyz="0 0 0" rpy="0 0 0"/>
            <geometry>
                <mesh filename="file://$(find moria_description)/meshes/left_wheel.STL"/>
            </geometry>
        </collision>
        <inertial>
            <origin xyz="0 0 0" rpy="0 0 0"/>
            <mass value="0.09111"/>
            <inertia 
                ixx="9.34E-05" ixy="1.34E-20" ixz="5.83E-17"
                iyy="9.34E-05" iyz="-2.18E-21"
                izz="0.00014" />
        </inertial>
    </link>




    <!-- LEG -->
    <joint name="leg_joint" type="fixed">
        <parent link="base_link"/>
        <child link="leg"/>
        <origin xyz="0.1 0 0.195" rpy="0 0 0"/>
    </joint>

    <link name="leg">
        <visual>
            <origin xyz="0 0 0" rpy="0 0 0"/>
            <geometry>
                <mesh filename="file://$(find moria_description)/meshes/leg.STL"/>
            </geometry>
            <material name="blue">
                <color rgba="0.0667 0.2431 0.4078 1"/>
            </material>
        </visual>
        <collision>
            <origin xyz="0 0 0" rpy="0 0 0"/>
            <geometry>
                <mesh filename="file://$(find moria_description)/meshes/leg.STL"/>
            </geometry>
        </collision>
        <inertial>
            <origin xyz="0 0 0" rpy="0 0 0"/>
            <mass value="${leg_mass}"/>
            <inertia 
                ixx="0.05454" ixy="-1.01E-06" ixz="-4.36E-06"
                iyy="0.04937" iyz="1.05E-06"
                izz="0.00671" />
        </inertial>
    </link>




    <!-- BODY-->
    <joint name="body_link" type="fixed">
        <parent link="leg"/>
        <child link="body"/>
        <origin xyz="0 0 0.482" rpy="0 0 0"/>
    </joint>

    <link name="body">
        <visual>
            <origin xyz="0 0 0" rpy="0 0 0"/>
            <geometry>
                <mesh filename="file://$(find moria_description)/meshes/body.STL"/>
            </geometry>
            <material name="blue">
                <color rgba="0.0667 0.2431 0.4078 1"/>
            </material>
        </visual>
        <collision>
            <origin xyz="0 0 0" rpy="0 0 0"/>
            <geometry>
                <mesh filename="file://$(find moria_description)/meshes/body.STL"/>
            </geometry>
        </collision>
        <inertial>
            <origin xyz="0 0 0" rpy="0 0 0"/>
            <mass value="${body_mass}"/>
            <inertia 
                ixx="0.05158" ixy="8.05E-06" ixz="-0.00031"
                iyy="0.03763" iyz="-3.04E-05"
                izz="0.02480" />
        </inertial>
    </link>




    <!-- HEAD-->
    <joint name="neck_joint" type="fixed"> <!-- rev-->
        <parent link="body"/>
        <child link="neck"/>
        <origin xyz="0.0091941 0 0.5456" rpy="0 0 0"/>
        <!--<axis xyz="0 0 1"/>
        <limit
            lower="-0.5"
            upper="0.5"
            effort="0"
            velocity="0"/>-->
    </joint>

    <link name="neck">
        <visual>
            <origin xyz="0 0 0" rpy="0 0 0"/>
            <geometry>
                <mesh filename="file://$(find moria_description)/meshes/neck.STL"/>
            </geometry>
            <material name="cyan">
                <color rgba="0.3137 0.6941 0.7843 1"/>
            </material>
        </visual>
        <collision>
            <origin xyz="0 0 0" rpy="0 0 0"/>
            <geometry>
                <mesh filename="file://$(find moria_description)/meshes/neck.STL"/>
            </geometry>
        </collision>
        <inertial>
            <origin xyz="0 0 0" rpy="0 0 0"/>
            <mass value="0.046"/>
            <inertia 
                ixx="1.24E-05" ixy="-5.24E-12" ixz="2.28E-09"
                iyy="1.04E-05" iyz="-1.81E-07"
                izz="7.77E-06" />
        </inertial>
    </link>


    <joint name="head_joint" type="fixed"> <!-- rev-->
        <parent link="neck"/>
        <child link="head"/>
        <origin xyz="-0.004 0.0004 0.0418" rpy="1.5708 0 0"/>
        <!--<axis xyz="0 0 1"/>
        <limit
            lower="-0.2"
            upper="0.2"
            effort="0"
            velocity="0"/> -->       
    </joint>

    <link name="head">
        <visual>
            <origin xyz="0 0 0" rpy="0 0 0"/>
            <geometry>
                <mesh filename="file://$(find moria_description)/meshes/head.STL"/>
            </geometry>
            <material name="cyan">
                <color rgba="0.3137 0.6941 0.7843 1"/>
            </material>
        </visual>
        <collision>
            <origin xyz="0 0 0" rpy="0 0 0"/>
            <geometry>
                <mesh filename="file://$(find moria_description)/meshes/head.STL"/>
            </geometry>
        </collision>
        <inertial>
            <origin xyz="0 0 0" rpy="0 0 0"/>
            <mass value="${head_mass}"/>
            <inertia 
                ixx="0.00448" ixy="-5.13E-05" ixz="4.01E-07"
                iyy="0.00293" iyz="1.42E-06"
                izz="0.00227" />
        </inertial>
    </link>

    <xacro:include filename="sensors.xacro"/>
    <xacro:include filename="fixed_right_arm.xacro"/>
    <xacro:include filename="fixed_left_arm.xacro"/>
    
</robot>
