<?xml version="1.0"?>
<robot xmlns:xacro="http://www.ros.org/wiki/xacro">

    <!-- RIGHT ARM-->
    <joint name="right_shoulder_rad_joint" type="revolute">
        <parent link="body"/>
        <child link="right_shoulder_rad"/>
        <origin xyz="0 -0.1585 0.503" rpy="1.5708 0 0"/>
        <axis xyz="0 0 1"/>
        <limit 
            lower="-1"
            upper="2.5"
            effort="3.7"
            velocity="0.22"/>
    </joint>

    <link name="right_shoulder_rad">
        <visual>
            <origin xyz="0 0 0" rpy="0 0 0"/>
            <geometry>
                <mesh 
                    filename="file://$(find moria_description)/meshes/right_shoulder_rad.STL"/>
            </geometry>
            <material name="blue">
                <color rgba="0.0667 0.2431 0.4078 1"/>
            </material>
        </visual>

        <collision>
            <origin xyz="0 0 0" rpy="0 0 0"/>
            <geometry>
                <mesh filename="file://$(find moria_description)/meshes/right_shoulder_rad.STL"/>
            </geometry>
        </collision>

        <inertial>
            <origin xyz="0 0 0" rpy="0 0 0"/>
            <mass value="${shoulder_rad_mass}"/>
            <inertia 
                ixx="7.14E-05" ixy="-2.01E-09" ixz="9.48E-07"
                iyy="6.21E-05" iyz="7.42E-07"
                izz="3.74E-05" />
        </inertial>
    </link>




    <joint name="right_shoulder_joint" type="revolute">
        <parent link="right_shoulder_rad"/>
        <child link="right_shoulder"/>
        <origin xyz="0.0252 0 0.059" rpy="1.5708 0 1.5708"/>
        <axis xyz="0 0 -1"/>
        <limit 
            lower="-1"
            upper="2.5"
            effort="3.7"
            velocity="0.22"/>
    </joint>

    <link name="right_shoulder">
        <visual>
            <origin xyz="0 0 0" rpy="0 0 0"/>
            <geometry>
                <mesh filename="file://$(find moria_description)/meshes/right_shoulder.STL"/>
            </geometry>
            <material name="cyan">
                <color rgba="0.3137 0.6941 0.7843 1"/>
            </material>
        </visual>
        <collision>
            <origin xyz="0 0 0" rpy="0 0 0"/>
            <geometry>
                <mesh filename="file://$(find moria_description)/meshes/right_shoulder.STL"/>
            </geometry>
        </collision>
        <inertial>
            <origin xyz="0 0 0" rpy="0 0 0"/>
            <mass value="${shoulder_mass}"/>
            <inertia 
                ixx="7.07E-05" ixy="-5.76E-06" ixz="-3.18E-06"
                iyy="0.00010" iyz="-3.29E-07"
                izz="0.00011" />
        </inertial>
    </link>




    <!-- UPPER ARM-->
    <joint name="right_upper_arm_joint" type="revolute">
        <parent link="right_shoulder"/>
        <child link="right_upper_arm"/>
        <origin xyz="-0.0855 0 -0.0255" rpy="0 -1.57 3.14"/>
        <axis xyz="0 0 1"/>
        <limit 
            lower="-1"
            upper="2.5"
            effort="3.7"
            velocity="0.22"/>
    </joint>

    <link name="right_upper_arm">
        <visual>
            <origin xyz="0 0 0" rpy="0 0 0"/>
            <geometry>
                <mesh filename="file://$(find moria_description)/meshes/right_upper_arm.STL"/>
            </geometry>
            <material name="blue">
                <color rgba="0.0667 0.2431 0.4078 1"/>
            </material>
        </visual>
        <collision>
            <origin xyz="0 0 0" rpy="0 0 0"/>
            <geometry>
                <mesh filename="file://$(find moria_description)/meshes/right_upper_arm.STL"/>
            </geometry>
        </collision>
        <inertial>
            <origin xyz="0 0 0" rpy="0 0 0"/>
            <mass value="${upper_arm_mass}"/>
            <inertia 
                ixx="0.00023" ixy="-4.99E-10" ixz="-5.62E-07"
                iyy="0.00021" iyz="-1.80E-07"
                izz="5.01E-05" />
        </inertial>
    </link>




    <!-- RIGHT ELBOW-->
    <joint name="right_elbow_joint" type="revolute">
        <parent link="right_upper_arm"/>
        <child link="right_elbow"/>
        <origin xyz="0 0.0228 -0.1432" rpy="-1.5708 0 0"/>
        <axis xyz="0 0 -1"/>
        <limit 
            lower="-1"
            upper="2.5"
            effort="3.7"
            velocity="0.22"/>
    </joint>

    <link name="right_elbow">
        <visual>
            <origin xyz="0 0 0" rpy="0 0 0"/>
            <geometry>
                <mesh filename="file://$(find moria_description)/meshes/right_elbow.STL"/>
            </geometry>
            <material name="cyan">
                <color rgba="0.3137 0.6941 0.7843 1"/>
            </material>
        </visual>
        <collision>
            <origin xyz="0 0 0" rpy="0 0 0"/>
            <geometry>
                <mesh filename="file://$(find moria_description)/meshes/right_elbow.STL"/>
            </geometry>
        </collision>
        <inertial>
            <origin xyz="0 0 0" rpy="0 0 0"/>
            <mass value="${elbow_mass}"/>
            <inertia 
                ixx="9.91E-05" ixy="-1.49E-06" ixz="2.12E-06"
                iyy="5.33E-05" iyz="4.53E-06"
                izz="8.43E-05" />
        </inertial>
    </link>




    <!-- RIGHT LOWER ARM-->
    <joint name="right_lower_arm_joint" type="revolute">
        <parent link="right_elbow"/>
        <child link="right_lower_arm"/>
        <origin xyz="0 0.0846 -0.0232" rpy="1.5708 0 0"/>
        <axis xyz="0 0 1"/>
        <limit 
            lower="-1"
            upper="2.5"
            effort="3.7"
            velocity="0.22"/>
    </joint>

    <link name="right_lower_arm">
        <visual>
            <origin xyz="0 0 0" rpy="0 0 0"/>
            <geometry>
                <mesh filename="file://$(find moria_description)/meshes/right_lower_arm.STL"/>
            </geometry>
            <material name="blue">
                <color rgba="0.0667 0.2431 0.4078 1"/>
            </material>
        </visual>
        <collision>
            <origin xyz="0 0 0" rpy="0 0 0"/>
            <geometry>
                <mesh filename="file://$(find moria_description)/meshes/right_lower_arm.STL"/>
            </geometry>
        </collision>
        <inertial>
            <origin xyz="0 0 0" rpy="0 0 0"/>
            <mass value="${lower_arm_mass}"/>
            <inertia 
                ixx="0.00032" ixy="7.23E-07" ixz="4.06E-07"
                iyy="0.00033" iyz="-3.36E-06"
                izz="0.00012" />
        </inertial>
    </link>




    <!-- RIGHT THUMB-->
    <joint name="right_00_joint" type="revolute">
        <parent link="right_lower_arm"/>
        <child link="right_00"/>
        <origin xyz="0.02860 -0.0019 -0.1878" rpy="2.7486 0.0097 1.5668"/>
        <axis xyz="0 0 -1"/>
        <limit 
            lower="-1"
            upper="2.5"
            effort="3.7"
            velocity="0.22"/>
    </joint>

    <link name="right_00">
        <visual>
            <origin xyz="0 0 0" rpy="0 0 0"/>
            <geometry>
                <mesh filename="file://$(find moria_description)/meshes/right_00.STL"/>
            </geometry>
            <material name="cyan">
                <color rgba="0.3137 0.6941 0.7843 1"/>
            </material>
        </visual>
        <collision>
            <origin xyz="0 0 0" rpy="0 0 0"/>
            <geometry>
                <mesh filename="file://$(find moria_description)/meshes/right_00.STL"/>
            </geometry>
        </collision>
        <inertial>
            <origin xyz="0 0 0" rpy="0 0 0"/>
            <mass value="0.005"/>
            <inertia 
                ixx="3E-07" ixy="0.0" ixz="0.0"
                iyy="2E-07" iyz="0.0"
                izz="2E-07" />
        </inertial>
    </link>

    <joint name="right_01_joint" type="revolute">
        <parent link="right_00"/>
        <child link="right_01"/>
        <origin xyz="-0.0020 0.0250 0.0034" rpy="0.3730 -0.4871 -0.1847"/>
        <axis xyz="0 0 -1"/>
        <limit 
            lower="-1"
            upper="2.5"
            effort="3.7"
            velocity="0.22"/>
    </joint>

    <link name="right_01">
        <visual>
            <origin xyz="0 0 0" rpy="0 0 0"/>
            <geometry>
                <mesh filename="file://$(find moria_description)/meshes/right_01.STL"/>
            </geometry>
            <material name="cyan">
                <color rgba="0.3137 0.6941 0.7843 1"/>
            </material>
        </visual>
        <collision>
            <origin xyz="0 0 0" rpy="0 0 0"/>
            <geometry>
                <mesh filename="file://$(find moria_description)/meshes/right_01.STL"/>
            </geometry>
        </collision>
        <inertial>
            <origin xyz="0 0 0" rpy="0 0 0"/>
            <mass value="0.002"/>
            <inertia 
                ixx="1E-07" ixy="0.0" ixz="0.0"
                iyy="1E-07" iyz="0.0"
                izz="8E-08" />
        </inertial>
    </link>

    <joint name="right_02_joint" type="revolute">
        <parent link="right_01"/>
        <child link="right_02"/>
        <origin xyz="0.017949 0.01744 0" rpy="0 0 0"/>
        <axis xyz="0 0 -1"/>
        <limit 
            lower="-1"
            upper="2.5"
            effort="3.7"
            velocity="0.22"/>
    </joint>

    <link name="right_02">
        <visual>
            <origin xyz="0 0 0" rpy="0 0 0"/>
            <geometry>
                <mesh filename="file://$(find moria_description)/meshes/right_02.STL"/>
            </geometry>
            <material name="cyan">
                <color rgba="0.3137 0.6941 0.7843 1"/>
            </material>
        </visual>
        <collision>
            <origin xyz="0 0 0" rpy="0 0 0"/>
            <geometry>
                <mesh filename="file://$(find moria_description)/meshes/right_02.STL"/>
            </geometry>
        </collision>
        <inertial>
            <origin xyz="0 0 0" rpy="0 0 0"/>
            <mass value="0.002"/>
            <inertia 
                ixx="6E-08" ixy="0.0" ixz="0.0"
                iyy="6E-08" iyz="0.0"
                izz="7E-08" />
        </inertial>
    </link>




    <!--RIGHT INDEX-->
    <joint name="right_10_joint" type="revolute">
        <parent link="right_lower_arm"/>
        <child link="right_10"/>
        <origin xyz="0.0267 -0.0027 -0.2479" rpy="1.5708 0 1.5708"/>
        <axis xyz="0 0 1"/>
        <limit 
            lower="-1"
            upper="2.5"
            effort="3.7"
            velocity="0.22"/>
    </joint>

    <link name="right_10">
        <visual>
            <origin xyz="0 0 0" rpy="0 0 0"/>
            <geometry>
                <mesh filename="file://$(find moria_description)/meshes/right_10.STL"/>
            </geometry>
            <material name="cyan">
                <color rgba="0.3137 0.6941 0.7843 1"/>
            </material>
        </visual>
        <collision>
            <origin xyz="0 0 0" rpy="0 0 0"/>
            <geometry>
                <mesh filename="file://$(find moria_description)/meshes/right_10.STL"/>
            </geometry>
        </collision>
        <inertial>
            <origin xyz="0 0 0" rpy="0 0 0"/>
            <mass value="0.002"/>
            <inertia 
                ixx="8E-08" ixy="0.0" ixz="0.0"
                iyy="6E-08" iyz="0.0"
                izz="6E-08" />
        </inertial>
    </link>

    <joint name="right_11_joint" type="revolute">
        <parent link="right_10"/>
        <child link="right_11"/>
        <origin xyz="-0.0003 -0.0239 0" rpy="0 0 0"/>
        <axis xyz="0 0 1"/>
        <limit 
            lower="-1"
            upper="2.5"
            effort="3.7"
            velocity="0.22"/>
    </joint>

    <link name="right_11">
        <visual>
            <origin xyz="0 0 0" rpy="0 0 0"/>
            <geometry>
                <mesh filename="file://$(find moria_description)/meshes/right_11.STL"/>
            </geometry>
            <material name="cyan">
                <color rgba="0.3137 0.6941 0.7843 1"/>
            </material>
        </visual>
        <collision>
            <origin xyz="0 0 0" rpy="0 0 0"/>
            <geometry>
                <mesh filename="file://$(find moria_description)/meshes/right_11.STL"/>
            </geometry>
        </collision>
        <inertial>
            <origin xyz="0 0 0" rpy="0 0 0"/>
            <mass value="0.002"/>
            <inertia 
                ixx="6E-08" ixy="0.0" ixz="0.0"
                iyy="5E-08" iyz="0.0"
                izz="6E-08" />
        </inertial>
    </link>

    <joint name="right_12_joint" type="revolute">
        <parent link="right_11"/>
        <child link="right_12"/>
        <origin xyz="0.0039 -0.0208 0.0015" rpy="0 0 0"/>
        <axis xyz="0 0 1"/>
        <limit 
            lower="-1"
            upper="2.5"
            effort="3.7"
            velocity="0.22"/>
    </joint>

    <link name="right_12">
        <visual>
            <origin xyz="0 0 0" rpy="0 0 0"/>
            <geometry>
                <mesh filename="file://$(find moria_description)/meshes/right_12.STL"/>
            </geometry>
            <material name="cyan">
                <color rgba="0.3137 0.6941 0.7843 1"/>
            </material>
        </visual>
        <collision>
            <origin xyz="0 0 0" rpy="0 0 0"/>
            <geometry>
                <mesh filename="file://$(find moria_description)/meshes/right_12.STL"/>
            </geometry>
        </collision>
        <inertial>
            <origin xyz="0 0 0" rpy="0 0 0"/>
            <mass value="0.002"/>
            <inertia 
                ixx="4E-08" ixy="0.0" ixz="0.0"
                iyy="3E-08" iyz="0.0"
                izz="4E-08" />
        </inertial>
    </link>




    <!--RIGHT MIDDLE-->
    <joint name="right_20_joint" type="revolute">
        <parent link="right_lower_arm"/>
        <child link="right_20"/>
        <origin xyz="0.0092 -0.0026 -0.2478" rpy="1.5708 0 1.5708"/>
        <axis xyz="0 0 1"/>
        <limit 
            lower="-1"
            upper="2.5"
            effort="3.7"
            velocity="0.22"/>
    </joint>

    <link name="right_20">
        <visual>
            <origin xyz="0 0 0" rpy="0 0 0"/>
            <geometry>
                <mesh filename="file://$(find moria_description)/meshes/right_20.STL"/>
            </geometry>
            <material name="cyan">
                <color rgba="0.3137 0.6941 0.7843 1"/>
            </material>
        </visual>
        <collision>
            <origin xyz="0 0 0" rpy="0 0 0"/>
            <geometry>
                <mesh filename="file://$(find moria_description)/meshes/right_20.STL"/>
            </geometry>
        </collision>
        <inertial>
            <origin xyz="0 0 0" rpy="0 0 0"/>
            <mass value="0.003"/>
            <inertia 
                ixx="1E-07" ixy="0.0" ixz="0.0"
                iyy="1E-07" iyz="0.0"
                izz="1E-07" />
        </inertial>
    </link>

    <joint name="right_21_joint" type="revolute">
        <parent link="right_20"/>
        <child link="right_21"/>
        <origin xyz="-0.0002 -0.0265 0" rpy="0 0 0"/>
        <axis xyz="0 0 1"/>
        <limit 
            lower="-1"
            upper="2.5"
            effort="3.7"
            velocity="0.22"/>
    </joint>

    <link name="right_21">
        <visual>
            <origin xyz="0 0 0" rpy="0 0 0"/>
            <geometry>
                <mesh filename="file://$(find moria_description)/meshes/right_21.STL"/>
            </geometry>
            <material name="cyan">
                <color rgba="0.3137 0.6941 0.7843 1"/>
            </material>
        </visual>
        <collision>
            <origin xyz="0 0 0" rpy="0 0 0"/>
            <geometry>
                <mesh filename="file://$(find moria_description)/meshes/right_21.STL"/>
            </geometry>
        </collision>
        <inertial>
            <origin xyz="0 0 0" rpy="0 0 0"/>
            <mass value="0.002"/>
            <inertia 
                ixx="6E-08" ixy="0.0" ixz="0.0"
                iyy="6E-08" iyz="0.0"
                izz="8E-08" />
        </inertial>
    </link>

    <joint name="right_22_joint" type="revolute">
        <parent link="right_21"/>
        <child link="right_22"/>
        <origin xyz="0 -0.023 0.0002" rpy="0 0 0"/>
        <axis xyz="0 0 1"/>
        <limit 
            lower="-1"
            upper="2.5"
            effort="3.7"
            velocity="0.22"/>
    </joint>

    <link name="right_22">
        <visual>
            <origin xyz="0 0 0" rpy="0 0 0"/>
            <geometry>
                <mesh filename="file://$(find moria_description)/meshes/right_22.STL"/>
            </geometry>
            <material name="cyan">
                <color rgba="0.3137 0.6941 0.7843 1"/>
            </material>
        </visual>
        <collision>
            <origin xyz="0 0 0" rpy="0 0 0"/>
            <geometry>
                <mesh filename="file://$(find moria_description)/meshes/right_22.STL"/>
            </geometry>
        </collision>
        <inertial>
            <origin xyz="0 0 0" rpy="0 0 0"/>
            <mass value="0.002"/>
            <inertia 
                ixx="6E-08" ixy="0.0" ixz="0.0"
                iyy="6E-08" iyz="0.0"
                izz="8E-08" />
        </inertial>
    </link>




    <!--RIGHT RING-->
    <joint name="right_30_joint" type="revolute">
        <parent link="right_lower_arm"/>
        <child link="right_30"/>
        <origin xyz="-0.0082 -0.0026 -0.247" rpy="1.5708 0 1.5708"/>
        <axis xyz="0 0 1"/>
        <limit 
            lower="-1"
            upper="2.5"
            effort="3.7"
            velocity="0.22"/>
    </joint>

    <link name="right_30">
        <visual>
            <origin xyz="0 0 0" rpy="0 0 0"/>
            <geometry>
                <mesh filename="file://$(find moria_description)/meshes/right_30.STL"/>
            </geometry>
            <material name="cyan">
                <color rgba="0.3137 0.6941 0.7843 1"/>
            </material>
        </visual>
        <collision>
            <origin xyz="0 0 0" rpy="0 0 0"/>
            <geometry>
                <mesh filename="file://$(find moria_description)/meshes/right_30.STL"/>
            </geometry>
        </collision>
        <inertial>
            <origin xyz="0 0 0" rpy="0 0 0"/>
            <mass value="0.002"/>
            <inertia 
                ixx="8E-08" ixy="0.0" ixz="0.0"
                iyy="6E-08" iyz="0.0"
                izz="7E-08" />
        </inertial>
    </link>

    <joint name="right_31_joint" type="revolute">
        <parent link="right_30"/>
        <child link="right_31"/>
        <origin xyz="0.0006 -0.0239 0" rpy="0 0 0"/>
        <axis xyz="0 0 1"/>
        <limit 
            lower="-1"
            upper="2.5"
            effort="3.7"
            velocity="0.22"/>
    </joint>

    <link name="right_31">
        <visual>
            <origin xyz="0 0 0" rpy="0 0 0"/>
            <geometry>
                <mesh filename="file://$(find moria_description)/meshes/right_31.STL"/>
            </geometry>
            <material name="cyan">
                <color rgba="0.3137 0.6941 0.7843 1"/>
            </material>
        </visual>
        <collision>
            <origin xyz="0 0 0" rpy="0 0 0"/>
            <geometry>
                <mesh filename="file://$(find moria_description)/meshes/right_31.STL"/>
            </geometry>
        </collision>
        <inertial>
            <origin xyz="0 0 0" rpy="0 0 0"/>
            <mass value="0.002"/>
            <inertia 
                ixx="6E-08" ixy="0.0" ixz="0.0"
                iyy="5E-08" iyz="0.0"
                izz="6E-08" />
        </inertial>
    </link>

    <joint name="right_32_joint" type="revolute">
        <parent link="right_31"/>
        <child link="right_32"/>
        <origin xyz="0.0005 -0.0210 0" rpy="0 0 0"/>
        <axis xyz="0 0 1"/>
        <limit 
            lower="-1"
            upper="2.5"
            effort="3.7"
            velocity="0.22"/>
    </joint>

    <link name="right_32">
        <visual>
            <origin xyz="0 0 0" rpy="0 0 0"/>
            <geometry>
                <mesh filename="file://$(find moria_description)/meshes/right_32.STL"/>
            </geometry>
            <material name="cyan">
                <color rgba="0.3137 0.6941 0.7843 1"/>
            </material>
        </visual>
        <collision>
            <origin xyz="0 0 0" rpy="0 0 0"/>
            <geometry>
                <mesh filename="file://$(find moria_description)/meshes/right_32.STL"/>
            </geometry>
        </collision>
        <inertial>
            <origin xyz="0 0 0" rpy="0 0 0"/>
            <mass value="0.002"/>
            <inertia 
                ixx="4E-08" ixy="0.0" ixz="0.0"
                iyy="3E-08" iyz="0.0"
                izz="4E-08" />
        </inertial>
    </link>




    <!-- RIGHT PINKY-->
    <joint name="right_40_joint" type="revolute">
        <parent link="right_lower_arm"/>
        <child link="right_40"/>
        <origin xyz="-0.0257 -0.0027 -0.2480" rpy="1.5708 0 1.5708"/>
        <axis xyz="0 0 1"/>
        <limit 
            lower="-1"
            upper="2.5"
            effort="3.7"
            velocity="0.22"/>
    </joint>

    <link name="right_40">
        <visual>
            <origin xyz="0 0 0" rpy="0 0 0"/>
            <geometry>
                <mesh filename="file://$(find moria_description)/meshes/right_40.STL"/>
            </geometry>
            <material name="cyan">
                <color rgba="0.3137 0.6941 0.7843 1"/>
            </material>
        </visual>
        <collision>
            <origin xyz="0 0 0" rpy="0 0 0"/>
            <geometry>
                <mesh filename="file://$(find moria_description)/meshes/right_40.STL"/>
            </geometry>
        </collision>
        <inertial>
            <origin xyz="0 0 0" rpy="0 0 0"/>
            <mass value="0.002"/>
            <inertia 
                ixx="6E-08" ixy="0.0" ixz="0.0"
                iyy="4E-08" iyz="0.0"
                izz="4E-08" />
        </inertial>
    </link>

    <joint name="right_41_joint" type="revolute">
        <parent link="right_40"/>
        <child link="right_41"/>
        <origin xyz="0 -0.0231 0" rpy="0 0 0"/>
        <axis xyz="0 0 1"/>
        <limit 
            lower="-1"
            upper="2.5"
            effort="3.7"
            velocity="0.22"/>
    </joint>

    <link name="right_41">
        <visual>
            <origin xyz="0 0 0" rpy="0 0 0"/>
            <geometry>
                <mesh filename="file://$(find moria_description)/meshes/right_41.STL"/>
            </geometry>
            <material name="cyan">
                <color rgba="0.3137 0.6941 0.7843 1"/>
            </material>
        </visual>
        <collision>
            <origin xyz="0 0 0" rpy="0 0 0"/>
            <geometry>
                <mesh filename="file://$(find moria_description)/meshes/right_41.STL"/>
            </geometry>
        </collision>
        <inertial>
            <origin xyz="0 0 0" rpy="0 0 0"/>
            <mass value="0.002"/>
            <inertia 
                ixx="3E-08" ixy="0.0" ixz="0.0"
                iyy="3E-08" iyz="0.0"
                izz="3E-08" />
        </inertial>
    </link>

    <joint name="right_42_joint" type="revolute">
        <parent link="right_41"/>
        <child link="right_42"/>
        <origin xyz="-0.0014883 -0.018288 0" rpy="0 0 0"/>
        <axis xyz="0 0 1"/>
        <limit 
            lower="-1"
            upper="2.5"
            effort="3.7"
            velocity="0.22"/>
    </joint>

    <link name="right_42">
        <visual>
            <origin xyz="0 0 0" rpy="0 0 0"/>
            <geometry>
                <mesh filename="file://$(find moria_description)/meshes/right_42.STL"/>
            </geometry>
            <material name="cyan">
                <color rgba="0.3137 0.6941 0.7843 1"/>
            </material>
        </visual>
        <collision>
            <origin xyz="0 0 0" rpy="0 0 0"/>
            <geometry>
                <mesh filename="file://$(find moria_description)/meshes/right_42.STL"/>
            </geometry>
        </collision>
        <inertial>
            <origin xyz="0 0 0" rpy="0 0 0"/>
            <mass value="0.002"/>
            <inertia 
                ixx="1E-08" ixy="0.0" ixz="0.0"
                iyy="1E-08" iyz="0.0"
                izz="1E-08" />
        </inertial>
    </link>
</robot>
