<?xml version="1.0" ?>
<sdf version="1.5">
  <model name="moria">  
    <pose>0.0 0.0 0.0 0.0 0.0 0.0</pose>

    <!-- ::::::::::FLOOR DEFINITION - WORLD JOINT:::::::::: -->
	  <link name="floor"/>
    <link name="base_footprint"/>

    <joint name="base_footprint_joint" type="fixed">
      <parent>floor</parent>
      <child>base_footprint</child>
      <pose>0 0 0 0 0 1.57</pose>
    </joint>

    <!-- ::::::::::ROBOT DEFINITIONS::::::::::-->
    <!-- :::::::BASE DEFINITION:::::::-->

    <joint name="base_joint" type="fixed">
      <parent>base_footprint</parent>
      <child>base</child>
      <pose>0.0 0.0 0.010 0 0 0</pose>
    </joint>

    <link name="base">
      <inertial>
        <pose>-0.00044759 -0.044904 0.3116 0 0 0</pose>
        <inertia>
          <ixx>0.03787</ixx>
          <ixy>0</ixy>
          <ixz>0</ixz>
          <iyy>0.04356</iyy>
          <iyz>0</iyz>
          <izz>0.04447</izz>
        </inertia>
        <mass>3.027</mass>
      </inertial>

      <collision name="base_collision">
        <pose>0 0 0 0 0 0</pose>
        <geometry>
          <mesh>
            <uri>/home/kemaltml/moria_ws/install/moria_gazebo/share/moria_gazebo/model/meshes/base_link.STL</uri>
          </mesh>
        </geometry>
      </collision>

      <visual name="base_visual">
        <pose>0 0 0 0 0 0</pose>
        <geometry>
          <mesh>
            <uri>/home/kemaltml/moria_ws/install/moria_gazebo/share/moria_gazebo/model/meshes/base_link.STL</uri>
          </mesh>
        </geometry>
      </visual>
    </link>


    <!--::::::::::LEFT WHEEL DEFINITION::::::::::-->

    <joint name="left_wheel_joint" type="revolute">
      <parent>base</parent>
      <child>left_wheel</child>
      <pose>-0.13 -0.11 -0.33 -1.57 0 0</pose>
      <axis>
        <xyz>-1 0 0</xyz>
      </axis>
    </joint>

    <link name="left_wheel">
      <inertial>
        <pose>0 0 0 0 0 0</pose>
        <inertia>
          <ixx>0.000367527070561836</ixx>
          <ixy>1.34004260418671E-22</ixy>
          <ixz>-5.33690965701899E-21</ixz>
          <iyy>0.000213503945734901</iyy>
          <iyz>2.03287907341032E-20</iyz>
          <izz>0.000213503945734901</izz>
        </inertia>
        <mass>0.260752190247953</mass>
      </inertial>

      <collision name="left_wheel_collision">
        <pose>0 0 0 0 0 0</pose>
        <geometry>
          <mesh>
            <uri>/home/kemaltml/moria_ws/install/moria_gazebo/share/moria_gazebo/model/meshes/left_wheel.STL</uri>
          </mesh>
        </geometry>
        <surface>
          <!-- This friction pamareter don't contain reliable data!! -->
          <friction>
            <ode>
              <mu>100000.0</mu>
              <mu2>100000.0</mu2>
              <fdir1>0 0 0</fdir1>
              <slip1>0.0</slip1>
              <slip2>0.0</slip2>
            </ode>
          </friction>
          <contact>
            <ode>
              <soft_cfm>0</soft_cfm>
              <soft_erp>0.2</soft_erp>
              <kp>1e+5</kp>
              <kd>1</kd>
              <max_vel>0.01</max_vel>
              <min_depth>0.001</min_depth>
            </ode>
          </contact>
        </surface>
      </collision>

      <visual name="left_wheel_visual">
        <pose>0 0 0 0 0 0</pose>
        <geometry>
          <mesh>
            <uri>/home/kemaltml/moria_ws/install/moria_gazebo/share/moria_gazebo/model/meshes/left_wheel.STL</uri>
          </mesh>
        </geometry>
      </visual>
    </link>


    <!--::::::::::RIGHT WHEEL DEFINITION::::::::::-->

    <joint name="right_wheel_joint" type="revolute">
      <parent>base_link</parent>
      <child>right_wheel</child>
      <pose>0.13 -0.11 -0.33 1.57 0 0</pose>
      <axis>
        <xyz>-1 0 0</xyz>
      </axis>
    </joint>

    <link name="right_wheel">
      <inertial>
        <pose>0 0 0 0 0 0</pose>
        <inertia>
          <ixx>0.000367527070561836</ixx>
          <ixy>1.34004260418671E-22</ixy>
          <ixz>-5.33690965701899E-21</ixz>
          <iyy>0.000213503945734901</iyy>
          <iyz>2.03287907341032E-20</iyz>
          <izz>0.000213503945734901</izz>
        </inertia>
        <mass>0.260752190247953</mass>
      </inertial>

      <collision name="right_wheel_collision">
        <pose>0 0 0 0 0 0</pose>
        <geometry>
          <mesh>
            <uri>/home/kemaltml/moria_ws/install/moria_gazebo/share/moria_gazebo/model/meshes/right_wheel.STL</uri>
          </mesh>
        </geometry>
        <surface>
          <!-- This friction pamareter don't contain reliable data!! -->
          <friction>
            <ode>
              <mu>100000.0</mu>
              <mu2>100000.0</mu2>
              <fdir1>0 0 0</fdir1>
              <slip1>0.0</slip1>
              <slip2>0.0</slip2>
            </ode>
          </friction>
          <contact>
            <ode>
              <soft_cfm>0</soft_cfm>
              <soft_erp>0.2</soft_erp>
              <kp>1e+5</kp>
              <kd>1</kd>
              <max_vel>0.01</max_vel>
              <min_depth>0.001</min_depth>
            </ode>
          </contact>
        </surface>
      </collision>

      <visual name="right_wheel_visual">
        <pose>0 0 0 0 0 0</pose>
        <geometry>
          <mesh>
            <uri>/home/kemaltml/moria_ws/install/moria_gazebo/share/moria_gazebo/model/meshes/right_wheel.STL</uri>
          </mesh>
        </geometry>
      </visual>
    </link>


    <!--::::::::::CASTER WHEEL DEFINITION::::::::::-->

    <joint name='caster_joint' type='ball'>
      <parent>base_link</parent>
      <child>caster_link</child>
    </joint>

    <link name='caster_link'>
      <pose>0 0 0 0 0 0</pose>
      <inertial>
        <mass>0.001</mass>
        <inertia>
          <ixx>0.00001</ixx>
          <ixy>0.000</ixy>
          <ixz>0.000</ixz>
          <iyy>0.00001</iyy>
          <iyz>0.000</iyz>
          <izz>0.00001</izz>
        </inertia>
      </inertial>
      <collision name='collision'>
        <geometry>
          <sphere>
            <radius>0.005000</radius>
          </sphere>
        </geometry>
        <surface>
          <contact>
            <ode>
              <soft_cfm>0</soft_cfm>
              <soft_erp>0.2</soft_erp>
              <kp>1e+5</kp>
              <kd>1</kd>
              <max_vel>0.01</max_vel>
              <min_depth>0.001</min_depth>
            </ode>
          </contact>
        </surface>
      </collision>
    </link>



    <!-- ::::::::::LEGS DEFINITION:::::::::: -->
    <link name="legs">
      <inertial>
        <pose>3.13579670600497E-05 0.410501245279509 2.92613595315391E-05 0 0 0</pose>
        <inertia>
          <ixx>0.00974131860411503</ixx>
          <ixy>0</ixy>
          <ixz>0</ixz>
          <iyy>0.00435809920534734</iyy>
          <iyz>0</iyz>
          <izz>0.013324822888574</izz>
        </inertia>
        <mass>0.57830229100239</mass>
      </inertial>

      <collision name="legs_collision">
        <pose>0 0 0 0 0 0</pose>
        <geometry>
          <mesh>
            <uri>/home/kemaltml/moria_ws/install/moria_gazebo/share/moria_gazebo/model/meshes/legs.STL</uri>
          </mesh>
        </geometry>
      </collision>

      <visual name="legs_visual">
        <pose>0 0 0 0 0 0</pose>
        <geometry>
          <mesh>
            <uri>/home/kemaltml/moria_ws/install/moria_gazebo/share/moria_gazebo/model/meshes/legs.STL</uri>
          </mesh>
        </geometry>
      </visual>
    </link>


    <!-- ::::::::::BODY DEFINITION:::::::::: -->
    <link name="body">
      <inertial>
        <pose>3.13579670600497E-05 0.410501245279509 2.92613595315391E-05 0 0 0</pose>
        <inertia>
          <ixx>0.0131456950439134</ixx>
          <ixy>0</ixy>
          <ixz>0</ixz>
          <iyy>0.00972108230104261</iyy>
          <iyz>0</iyz>
          <izz>0.00846288278820841</izz>
        </inertia>
        <mass>0.716072236536923</mass>
      </inertial>

      <collision name="body_collision">
        <pose>0 0 0 0 0 0</pose>
        <geometry>
          <mesh>
            <uri>/home/kemaltml/moria_ws/install/moria_gazebo/share/moria_gazebo/model/meshes/body.STL</uri>
          </mesh>
        </geometry>
      </collision>

      <visual name="body_visual">
        <pose>0 0 0 0 0 0</pose>
        <geometry>
          <mesh>
            <uri>/home/kemaltml/moria_ws/install/moria_gazebo/share/moria_gazebo/model/meshes/body.STL</uri>
          </mesh>
        </geometry>
      </visual>
    </link>







    <!--::::::::::::::::::::SENSORS::::::::::::::::::::-->
    <!--::::::::::IMU SENSOR::::::::::-->

    <joint name="imu_joint" type="fixed">
      <parent>base</parent>
      <child>imu_link</child>
      <pose>0 0 -0.33 0 0 0</pose>
      <axis>
        <xyz>0 0 1</xyz>
      </axis>
    </joint>

    <link name="imu_link">
      <sensor name="moria_imu" type="imu">
        <always_on>true</always_on>
        <update_rate>200</update_rate>
        <imu>
          <angular_velocity>
            <x>
              <noise type="gaussian">
                <mean>0.0</mean>
                <stddev>2e-4</stddev>
              </noise>
            </x>
            <y>
              <noise type="gaussian">
                <mean>0.0</mean>
                <stddev>2e-4</stddev>
              </noise>
            </y>
            <z>
              <noise type="gaussian">
                <mean>0.0</mean>
                <stddev>2e-4</stddev>
              </noise>
            </z>
          </angular_velocity>
          <linear_acceleration>
            <x>
              <noise type="gaussian">
                <mean>0.0</mean>
                <stddev>1.7e-2</stddev>
              </noise>
            </x>
            <y>
              <noise type="gaussian">
                <mean>0.0</mean>
                <stddev>1.7e-2</stddev>
              </noise>
            </y>
            <z>
              <noise type="gaussian">
                <mean>0.0</mean>
                <stddev>1.7e-2</stddev>
              </noise>
            </z>
          </linear_acceleration>
        </imu>
        <plugin name="moria_imu" filename="libgazebo_ros_imu_sensor.so">
          <ros>
            <remapping>~/out:=imu</remapping>
          </ros>
        </plugin>
      </sensor>
    </link>



    <!--::::::::::FRONT LIDAR SENSOR::::::::::-->
    <joint name="scan_joint_f" type="fixed">
      <parent>base</parent>
      <child>base_scan_f</child>
      <pose>0 0.12 -0.15 0 0 -1.57</pose>
      <axis>
        <xyz>0 0 1</xyz>
      </axis>
    </joint>

    <link name="base_scan_f">
      <inertial>
        <pose>0 0 0 0 0 0</pose>
        <inertia>
          <ixx>0.001</ixx>
          <ixy>0.000</ixy>
          <ixz>0.000</ixz>
          <iyy>0.001</iyy>
          <iyz>0.000</iyz>
          <izz>0.001</izz>
        </inertia>
        <mass>0.114</mass>
      </inertial>

      <collision name="lidar_sensor_f_collision">
        <pose>0 0 0 0.015 0 -0.0065</pose>
        <geometry>
          <cylinder>
            <radius>0.0508</radius>
            <length>0.055</length>
          </cylinder>
        </geometry>
      </collision>

      <visual name="lidar_sensor_f_visual">
        <pose>0 0 0 0 0 0</pose>
        <geometry>
          <mesh>
            <uri>/home/kemaltml/moria_ws/install/moria_gazebo/share/moria_gazebo/model/meshes/lidar.stl</uri>
            <scale>0.001 0.001 0.001</scale>
          </mesh>
        </geometry>
      </visual>

      <sensor name="front_lidar" type="ray">
        <always_on>true</always_on>
        <visualize>true</visualize>
        <pose>0 0.12 -0.15 0 0 -1.57</pose>
        <update_rate>5</update_rate>
        <ray>
          <scan>
            <horizontal>
              <samples>180</samples>
              <resolution>1.000000</resolution>
              <min_angle>1.57</min_angle>
              <max_angle>4.71</max_angle>
            </horizontal>
          </scan>
          <range>
            <min>0.2</min>
            <max>3.5</max>
            <resolution>0.015000</resolution>
          </range>
          <noise>
            <type>gaussian</type>
            <mean>0.0</mean>
            <stddev>0.01</stddev>
          </noise>
        </ray>
        <plugin name="moria_front_laserscan" filename="libgazebo_ros_ray_sensor.so">
          <ros>
            <!-- <namespace>/tb3</namespace> -->
            <remapping>~/out:=scan_front</remapping>
          </ros>
          <output_type>sensor_msgs/LaserScan</output_type>
          <frame_name>base_scan_f</frame_name>
        </plugin>
      </sensor>
    </link>
    

    <!-- ::::::::::BACK LIDAR SENSOR:::::::::: -->

    <joint name="scan_joint_b" type="fixed">
      <parent>base</parent>
      <child>base_scan_b</child>
      <pose>0 -0.18 -0.15 0 0 1.57</pose>
      <axis>
        <xyz>0 0 1</xyz>
      </axis>
    </joint>

    <link name="base_scan_b">
      <inertial>
        <pose>0 0 0 0 0 0</pose>
        <inertia>
          <ixx>0.001</ixx>
          <ixy>0.000</ixy>
          <ixz>0.000</ixz>
          <iyy>0.001</iyy>
          <iyz>0.000</iyz>
          <izz>0.001</izz>
        </inertia>
        <mass>0.114</mass>
      </inertial>

      <collision name="lidar_sensor_b_collision">
        <pose>0 0 0 0.015 0 -0.0065</pose>
        <geometry>
          <cylinder>
            <radius>0.0508</radius>
            <length>0.055</length>
          </cylinder>
        </geometry>
      </collision>

      <visual name="lidar_sensor_b_visual">
        <pose>0 0 0 0 0 0</pose>
        <geometry>
          <mesh>
            <uri>/home/kemaltml/moria_ws/install/moria_gazebo/share/moria_gazebo/model/meshes/lidar.stl</uri>
            <scale>0.001 0.001 0.001</scale>
          </mesh>
        </geometry>
      </visual>

      <sensor name="back_lidar" type="ray">
        <always_on>true</always_on>
        <visualize>true</visualize>
        <pose>0 -0.18 -0.15 0 0 1.57</pose>
        <update_rate>5</update_rate>
        <ray>
          <scan>
            <horizontal>
              <samples>180</samples>
              <resolution>1.000000</resolution>
              <min_angle>1.57</min_angle>
              <max_angle>4.71</max_angle>
            </horizontal>
          </scan>
          <range>
            <min>0.2</min>
            <max>3.5</max>
            <resolution>0.015000</resolution>
          </range>
          <noise>
            <type>gaussian</type>
            <mean>0.0</mean>
            <stddev>0.01</stddev>
          </noise>
        </ray>
        <plugin name="moria_back_laserscan" filename="libgazebo_ros_ray_sensor.so">
          <ros>
            <!-- <namespace>/tb3</namespace> -->
            <remapping>~/out:=scan_back</remapping>
          </ros>
          <output_type>sensor_msgs/LaserScan</output_type>
          <frame_name>base_scan_b</frame_name>
        </plugin>
      </sensor>
    </link>
    

    <!--::::::::::CAMERA DEFINITIONS::::::::::-->

    <joint name="camera_joint" type="fixed">
      <parent>body</parent>
      <child>camera</child>
      <pose>0.11656 0.00021246 0.40556 1.9635 0.014384 1.5807</pose>
      <axis>
        <xyz>0 0 1</xyz>
      </axis>
    </joint>

    <link name="camera"/>



    <joint name="camera_rgb_joint" type="fixed">
      <parent>camera</parent>
      <child>camera_rgb_frame</child>
      <pose>0.005 0.018 0.013 0 -1.57 -1.57</pose>
      <axis>
        <xyz>0 0 1</xyz>
      </axis>
    </joint>

    <link name="camera_rgb_frame">
      <inertial>
        <pose>0.005 0.018 0.013 0 -1.57 -1.57</pose>
        <inertia>
          <ixx>0.001</ixx>
          <ixy>0.000</ixy>
          <ixz>0.000</ixz>
          <iyy>0.001</iyy>
          <iyz>0.000</iyz>
          <izz>0.001</izz>
        </inertia>
        <mass>0.035</mass>
      </inertial>

      <visual name="camera_rgb_visual">
        <pose>0 0 0 0 0 0</pose>
        <geometry>
          <mesh>
            <uri>/home/kemaltml/moria_ws/install/moria_gazebo/share/moria_gazebo/model/meshes/camera.STL</uri>
          </mesh>
        </geometry>
      </visual>

      <pose>0 0 0 0 0 0</pose>
      <sensor name="camera_rgb" type="camera">
        <always_on>true</always_on>
        <visualize>true</visualize>
        <update_rate>30</update_rate>
        <camera name="intel_realsense_d435">
          <horizontal_fov>1.02974</horizontal_fov>
          <image>
            <width>1920</width>
            <height>1080</height>
            <format>R8G8B8</format>
          </image>
          <clip>
            <near>0.02</near>
            <far>300</far>
          </clip>
          <noise>
            <type>gaussian</type>
            <!-- Noise is sampled independently per pixel on each frame.
                  That pixel's noise value is added to each of its color
                  channels, which at that point lie in the range [0,1]. -->
            <mean>0.0</mean>
            <stddev>0.007</stddev>
          </noise>
        </camera>
          <plugin name="camera_driver" filename="libgazebo_ros_camera.so">
            <ros>
              <!-- <namespace>test_cam</namespace> -->
              <!-- <remapping>image_raw:=image_demo</remapping> -->
              <!-- <remapping>camera_info:=camera_info_demo</remapping> -->
            </ros>
            <!-- camera_name>omit so it defaults to sensor name</camera_name-->
            <!-- frame_name>omit so it defaults to link name</frameName-->
            <!-- <hack_baseline>0.07</hack_baseline> -->
          </plugin>
      </sensor>
    </link>



    <joint name="camera_depth_joint" type="fixed">
      <parent>camera</parent>
      <child>camera_depth_frame</child>
      <pose>0.005 0.018 0.013 0 -1.57 -1.57</pose>
      <axis>
        <xyz>0 0 1</xyz>
      </axis>
    </joint>

    <link name="camera_depth_frame">
      <inertial>
        <pose>0.005 0.028 0.013 0 -1.57 -1.57</pose>
        <inertia>
          <ixx>0.001</ixx>
          <ixy>0.000</ixy>
          <ixz>0.000</ixz>
          <iyy>0.001</iyy>
          <iyz>0.000</iyz>
          <izz>0.001</izz>
        </inertia>
        <mass>0.035</mass>
      </inertial>

      <pose>0 0 0 0 0 0</pose>
      <sensor name="camera_depth" type="camera">
        <always_on>true</always_on>
        <visualize>true</visualize>
        <update_rate>30</update_rate>
        <camera name="intel_realsense_d435_2">
          <horizontal_fov>1.02974</horizontal_fov>
          <image>
            <width>1920</width>
            <height>1080</height>
            <format>B8G8R8</format>
          </image>
          <clip>
            <near>0.02</near>
            <far>300</far>
          </clip>
          <noise>
            <type>gaussian</type>
            <!-- Noise is sampled independently per pixel on each frame.
                  That pixel's noise value is added to each of its color
                  channels, which at that point lie in the range [0,1]. -->
            <mean>0.0</mean>
            <stddev>0.007</stddev>
          </noise>
        </camera>
          <plugin name="camera_driver_depth" filename="libgazebo_ros_camera.so">
            <ros>
              <!-- <namespace>test_cam</namespace> -->
              <!-- <remapping>image_raw:=image_demo</remapping> -->
              <!-- <remapping>camera_info:=camera_info_demo</remapping> -->
            </ros>
            <!-- camera_name>omit so it defaults to sensor name</camera_name-->
            <!-- frame_name>omit so it defaults to link name</frameName-->
            <!-- <hack_baseline>0.07</hack_baseline> -->
          </plugin>
      </sensor>
    </link>



    <!-- ::::::::::::::::::::SENSORS DEFINITIONS FOR GAZEBO:::::::::::::::::::: -->

    <!--::::::::::DIFF DRIVE::::::::::-->
    <plugin name="moria_diff_drive" filename="libgazebo_ros_diff_drive.so">

      <ros>
        <!-- <namespace>/tb3</namespace> -->
      </ros>

      <update_rate>30</update_rate>

      <!-- wheels -->
      <left_joint>left_wheel_joint</left_joint>
      <right_joint>right_wheel_joint</right_joint>

      <!-- kinematics -->
      <wheel_separation>0.26</wheel_separation>
      <wheel_diameter>0.1</wheel_diameter>

      <!-- limits -->
      <max_wheel_torque>20</max_wheel_torque>
      <max_wheel_acceleration>1.0</max_wheel_acceleration>

      <command_topic>cmd_vel</command_topic>

      <!-- output -->
      <publish_odom>true</publish_odom>
      <publish_odom_tf>true</publish_odom_tf>
      <publish_wheel_tf>false</publish_wheel_tf>

      <odometry_topic>odom</odometry_topic>
      <odometry_frame>odom</odometry_frame>
      <robot_base_frame>base_footprint</robot_base_frame>

    </plugin>


    <!--::::::::::JOINT STATE::::::::::-->
    <plugin name="moria_joint_state" filename="libgazebo_ros_joint_state_publisher.so">
      <ros>
        <!-- <namespace>/tb3</namespace> -->
        <remapping>~/out:=joint_states</remapping>
      </ros>
      <update_rate>30</update_rate>
      <joint_name>left_wheel_joint</joint_name>
      <joint_name>right_wheel_joint</joint_name>
    </plugin>    

  </model>
</sdf>
