<?xml version="1.0" ?>
<!-- =================================================================================== -->
<!-- |    This document was autogenerated by xacro from moria.urdf.xacro               | -->
<!-- |    EDITING THIS FILE BY HAND IS NOT RECOMMENDED                                 | -->
<!-- =================================================================================== -->
<robot name="moria">
  <!--FLOOR DEFINITION - WORLD JOINT-->
  <link name="floor">
  </link>
  
  
  <!-- ROBOT DEFINITIONS-->
  <joint name="base_joint" type="fixed">
    <parent link="floor"/>
    <child link="base"/>
    <origin xyz="1 0 0.4"/>
  </joint>
  
  
  <!--BASE DEFINITION-->
  <link name="base">
    <visual>
      <origin xyz="0 0 0"/>
      <geometry>
        <mesh filename="model://moria_gazebo/model/meshes/base_link.STL"/>
      </geometry>
      <material name="">
        <color rgba="0.79216 0.11961 0.93333 1"/>
      </material>
    </visual>
    
    <inertial>
      <origin xyz="-0.00044759 -0.044904 0.3116"/>
      <mass value="3.027"/>
      <inertia ixx="0.03787" ixy="0.00001" ixz="0.00001" iyy="0.04356" iyz="0.00008" izz="0.04447"/>
    </inertial>
  </link>
  
  
  <!--LEFT WHEEL DEFINITION-->
  <joint name="left_wheel_joint" type="continuous">
    <parent link="base"/>
    <child link="left_wheel"/>
    <origin rpy="0 1.57 0" xyz="-0.13 -0.11 -0.33 "/>
    <axis xyz="0 0 -1"/>
  </joint>
  
  <link name="left_wheel">
    <visual>
      <origin rpy="0 0 0" xyz="0 0 0"/>
      <geometry>
        <cylinder length="0.04" radius="0.05"/>
      </geometry>
    </visual>
    
    <inertial>
      <origin rpy="0 0 0" xyz="0 0 0"/>
      <mass value="0.0261"/>
      <inertia ixx="1.9792500000000004e-05" ixy="0.0" ixz="0.0" iyy="1.9792500000000004e-05" iyz="0.0" izz="3.262500000000001e-05"/>
    </inertial>
  </link>
  
  
  <!--RIGHT WHEEL DEFINITION-->
  <joint name="right_wheel_joint" type="continuous">
    <parent link="base"/>
    <child link="right_wheel"/>
    <origin rpy="0 1.57 0" xyz="0.13 -0.11 -0.33"/>
    <axis xyz="0 0 -1"/>
  </joint>
  
  <link name="right_wheel">
    <visual>
      <origin rpy="0 0 0" xyz="0 0 0"/>
      <geometry>
        <cylinder length="0.04" radius="0.05"/>
      </geometry>
    </visual>
    
    <inertial>
      <origin rpy="0 0 0" xyz="0 0 0"/>
      <mass value="0.0261"/>
      <inertia ixx="1.9792500000000004e-05" ixy="0.0" ixz="0.0" iyy="1.9792500000000004e-05" iyz="0.0" izz="3.262500000000001e-05"/>
    </inertial>
  </link>
  
  
  <!--CASTER WHEEL DEFINITION-->
  <joint name="caster_joint" type="fixed">
    <parent link="base"/>
    <child link="caster_link"/>
    <origin rpy="0 0 0" xyz="0 0.12 -0.36"/>
  </joint>
  
  <link name="caster_link">
    <collision>
      <origin rpy="0 0 0" xyz="0 0.001 0"/>
      <geometry>
        <box size="0.02 0.02 0.02"/>
      </geometry>
      <surface>
        <contact>
          <ode>
            <soft_cfm>0</soft_cfm>
            <soft_erp>0.2</soft_erp>
            <kp>1e+5</kp>
            <kd>1</kd>
            <max_vel>0.01</max_vel>
            <min_depth>0.001</min_depth>
          </ode>
        </contact>
      </surface>
    </collision>
    
    <inertial>
      <origin xyz="0 0 0"/>
      <mass value="0.005"/>
      <inertia ixx="0.001" ixy="0.0" ixz="0.0" iyy="0.001" iyz="0.0" izz="0.001"/>
    </inertial>
  </link>
  
  
  <!-- LEGS DEFINITION-->
  <joint name="legs_joint" type="fixed">
    <origin rpy="1.5708 0 0" xyz="-0.0015188 -0.038639 -0.35111"/>
    <parent link="base"/>
    <child link="legs"/>
  </joint>
  
  <link name="legs">
    <inertial>
      <origin rpy="0 0 0" xyz="3.13579670600497E-05 0.410501245279509 2.92613595315391E-05"/>
      <mass value="0.57830229100239"/>
      <inertia ixx="0.00974131860411503" ixy="-2.4628489310393E-06" ixz="7.54615274060419E-08" iyy="0.00435809920534734" iyz="-2.95659056324959E-07" izz="0.013324822888574"/>
    </inertial>
    
    <visual>
      <origin rpy="0 0 0" xyz="0 0 0"/>
      <geometry>
        <mesh filename="model://moria_gazebo/model/meshes/legs.STL"/>
      </geometry>
      <material name="">
        <color rgba="0.792156862745098 0.819607843137255 0.933333333333333 1"/>
      </material>
    </visual>
    
    <collision>
      <origin rpy="0 0 0" xyz="0 0 0"/>
      <geometry>
        <mesh filename="model://moria_gazebo/model/meshes/legs.STL"/>
      </geometry>
    </collision>
  </link>
  
  
  <!--BODY DEFINITION-->
  <joint name="body_joint" type="fixed">
    <origin rpy="3.1416 1.4922 -1.5708" xyz="3.4229E-05 0.5421 0.029896"/>
    <parent link="legs"/>
    <child link="body"/>
  </joint>
  
  <link name="body">
    <inertial>
      <origin rpy="0 0 0" xyz="0.00690202806639532 -7.2816871036846E-05 0.330424705663419"/>
      <mass value="0.716072236536923"/>
      <inertia ixx="0.0131456950439134" ixy="-1.50886229692576E-06" ixz="0.000424054700669175" iyy="0.00972108230104261" iyz="6.38231130573314E-07" izz="0.00846288278820841"/>
    </inertial>
    
    <visual>
      <origin rpy="0 0 0" xyz="0 0 0"/>
      <geometry>
        <mesh filename="model://moria_gazebo/model/meshes/body.STL"/>
      </geometry>
      <material name="">
        <color rgba="0.792156862745098 0.819607843137255 0.933333333333333 1"/>
      </material>
    </visual>
    
    <collision>
      <origin rpy="0 0 0" xyz="0 0 0"/>
      <geometry>
        <mesh filename="model://moria_gazebo/model/meshes/body.STL"/>
      </geometry>
    </collision>
  </link>
  
  <plugin filename="libgazebo_ros_diff_drive.so" name="moria_diff_drive">
    <ros>

    </ros>
    <update_rate>30</update_rate>
    <left_joint>left_wheel_joint</left_joint>
    <right_joint>right_wheel_joint</right_joint>
    <wheel_seperation>0.26</wheel_seperation>
    <wheel_diameter>0.05</wheel_diameter>
    <max_wheel_torque>20</max_wheel_torque>
    <max_wheel_acceleration>1.0</max_wheel_acceleration>
    <command_topic>cmd_vel</command_topic>
    <publish_odom>true</publish_odom>
    <publish_odom_tf>true</publish_odom_tf>
    <publish_wheel_tf>false</publish_wheel_tf>
    <odometry_topic>odom</odometry_topic>
    <odometry_frame>odom</odometry_frame>
    <robot_base_frame>floor</robot_base_frame>
  </plugin>
  
  <plugin filename="libgazebo_ros_joint_state_publisher.so" name="moria_joint_state">
    <ros>
      <remapping>~/out:=joint_states</remapping>
    </ros>
    <update_rate>30</update_rate>
    <joint_name>left_wheel_joint</joint_name>
    <joint_name>right_wheel_joint</joint_name>
  </plugin>
  
  
  <!--IMU SENSOR-->
  <joint name="imu_joint" type="fixed">
    <parent link="base"/>
    <child link="imu"/>
    <origin rpy="0 0 0" xyz="0 0 -0.33"/>
  </joint>
  <link name="imu"/>
  
  
  <!--FRONT LIDAR SENSOR-->
  <joint name="scan_joint_f" type="fixed">
    <parent link="base"/>
    <child link="base_scan_f"/>
    <origin rpy="0 0 -1.57" xyz="0 0.12 -0.15"/>
  </joint>
  
  <link name="base_scan_f">
    <visual>
      <origin rpy="0 0 0" xyz="0 0 0"/>
      <geometry>
        <mesh filename="model://moria_gazebo/model/meshes/lidar.stl" scale="0.001 0.001 0.001"/>
      </geometry>
    </visual>
    
    <collision>
      <origin rpy="0 0 0" xyz="0.015 0 -0.0065"/>
      <geometry>
        <cylinder length="0.0315" radius="0.055"/>
      </geometry>
    </collision>
    
    <inertial>
      <mass value="0.114"/>
      <origin xyz="0 0 0"/>
      <inertia ixx="0.001" ixy="0.0" ixz="0.0" iyy="0.001" iyz="0.0" izz="0.001"/>
    </inertial>
  </link>
  
  
  <gazebo reference="scan_joint_f">
    <material>Gazebo/Red</material>
    <sensor name="scan_front" type="ray">
      <pose> 0 0 0 0 0 0 </pose>
      <visualize>true</visualize>
      <update_rate>10</update_rate>
      <ray>
        <scan>
          <horizontal>
            <samples>360</samples>
            <min_angle>-1.57</min_angle>
            <max_angle>1.57</max_angle>
          </horizontal>
        </scan>
        <range>
          <min>0.2</min>
          <max>12</max>
        </range>
      </ray>
      <plugin filename="libgazebo_ros_ray_sensor.so" name="laser_controller">
        <ros>
          <remapping>~/out:=scan</remapping>
        </ros>
        <output_type>sensor_msgs/LaserScan</output_type>
        <frame_name>front_scan</frame_name>
      </plugin>
    </sensor>
  </gazebo>
  
  
  <!--BACK LIDAR SENSOR-->
  <joint name="scan_joint_b" type="fixed">
    <parent link="base"/>
    <child link="base_scan_b"/>
    <origin rpy="0 0 1.57" xyz="0 -0.18 -0.15"/>
  </joint>
  
  <link name="base_scan_b">
    <visual>
      <origin rpy="0 0 0" xyz="0 0 0"/>
      <geometry>
        <mesh filename="model://moria_gazebo/model/meshes/lidar.stl" scale="0.001 0.001 0.001"/>
      </geometry>
    </visual>
    
    <collision>
      <origin rpy="0 0 0" xyz="0.015 0 -0.0065"/>
      <geometry>
        <cylinder length="0.0315" radius="0.055"/>
      </geometry>
    </collision>
    
    <inertial>
      <mass value="0.114"/>
      <origin xyz="0 0 0"/>
      <inertia ixx="0.001" ixy="0.0" ixz="0.0" iyy="0.001" iyz="0.0" izz="0.001"/>
    </inertial>
  </link>
  
  <gazebo reference="scan_joint_b">
    <material>Gazebo/Red</material>
    <sensor name="scan_back" type="ray">
      <pose> 0 0 0 0 0 0 </pose>
      <visualize>true</visualize>
      <update_rate>10</update_rate>
      <ray>
        <scan>
          <horizontal>
            <samples>360</samples>
            <min_angle>-1.57</min_angle>
            <max_angle>1.57</max_angle>
          </horizontal>
        </scan>
        <range>
          <min>0.2</min>
          <max>12</max>
        </range>
      </ray>
      <plugin filename="libgazebo_ros_ray_sensor.so" name="laser_controller">
        <ros>
          <remapping>~/out:=scan</remapping>
        </ros>
        <output_type>sensor_msgs/LaserScan</output_type>
        <frame_name>back_scan</frame_name>
      </plugin>
    </sensor>
  </gazebo>
  
  
  <!--CAMERA DEFINITIONS-->
  <joint name="camera_joint" type="fixed">
    <origin rpy="1.9635 0.014384 1.5807" xyz="0.11656 0.00021246 0.40556"/>
    <parent link="body"/>
    <child link="camera"/>
  </joint>
  
  <link name="camera">
    <inertial>
      <origin rpy="0 0 0" xyz="0.00111197944610194 -2.78407664494607E-05 -0.0125996882830277"/>
      <mass value="1.26688289972681"/>
      <inertia ixx="0.000114531950081501" ixy="-4.04797053674309E-08" ixz="1.13413908500607E-05" iyy="0.000771596398566531" iyz="2.05523327802103E-07" izz="0.000763733428436124"/>
    </inertial>
    <visual>
      <origin rpy="0 0 0" xyz="0 0 0"/>
      <geometry>
        <mesh filename="model://moria_gazebo/model/meshes/camera.STL"/>
      </geometry>
    </visual>
    <collision>
      <origin rpy="0 0 0" xyz="0 0 0"/>
      <geometry>
        <mesh filename="model://moria_gazebo/model/meshes/camera.STL"/>
      </geometry>
    </collision>
  </link>
  
  <gazebo reference="camera">
    <material>Gazebo/Red</material>
    <sensor name="camera" type="depth">
      <pose> 0 0 0 0 0 0 </pose>
      <visualize>true</visualize>
      <update_rate>10</update_rate>
      <camera>
        <horizontal_fov>1.089</horizontal_fov>
        <image>
          <format>B8G8R8</format>
          <width>640</width>
          <height>480</height>
        </image>
        <clip>
          <near>0.05</near>
          <far>8.0</far>
        </clip>
      </camera>
      <plugin filename="libgazebo_ros_camera.so" name="camera_controller">
        <frame_name>camera_link_optical</frame_name>
        <min_depth>0.1</min_depth>
        <max_depth>100.0</max_depth>
      </plugin>
    </sensor>
  </gazebo>
</robot>
